Workbook
Name grp: '대상자_VO2max'!$B$4:$B$33
Name inc: '대상자_VO2max'!$D$4:$D$33
Name vo2_pre: '대상자_VO2max'!$O$4:$O$33
Name vo2_post: '대상자_VO2max'!$X$4:$X$33
Name d_vo2: '대상자_VO2max'!$AF$4:$AF$33
Name wt_pre: '대상자_VO2max'!$N$4:$N$33
Name wt_post: '대상자_VO2max'!$W$4:$W$33
Name d_wt: '대상자_VO2max'!$AH$4:$AH$33
Name age: '대상자_VO2max'!$I$4:$I$33
Name height: '대상자_VO2max'!$J$4:$J$33
Name career: '대상자_VO2max'!$L$4:$L$33
Name sex: '대상자_VO2max'!$H$4:$H$33
Name grp_f: 'FMS'!$B$4:$B$33
Name inc_f: 'FMS'!$C$4:$C$33
Name fms_pre: 'FMS'!$BI$4:$BI$33
Name fms_post: 'FMS'!$BJ$4:$BJ$33
Name d_fms: 'FMS'!$BK$4:$BK$33
Name fms_avg_pre: 'FMS'!$BP$4:$BP$33
Name fms_avg_post: 'FMS'!$BQ$4:$BQ$33
Name d_fms_avg: 'FMS'!$BR$4:$BR$33
Name asym_pre: 'FMS'!$AW$4:$AW$33
Name asym_post: 'FMS'!$BG$4:$BG$33
Name DS_pre_s: 'FMS'!$AO$4:$AO$33
Name DS_post_s: 'FMS'!$AY$4:$AY$33
Name HS_pre_s: 'FMS'!$AP$4:$AP$33
Name HS_post_s: 'FMS'!$AZ$4:$AZ$33
Name ILL_pre_s: 'FMS'!$AQ$4:$AQ$33
Name ILL_post_s: 'FMS'!$BA$4:$BA$33
Name SM_pre_s: 'FMS'!$AR$4:$AR$33
Name SM_post_s: 'FMS'!$BB$4:$BB$33
Name ASLR_pre_s: 'FMS'!$AS$4:$AS$33
Name ASLR_post_s: 'FMS'!$BC$4:$BC$33
Name TSPU_pre_s: 'FMS'!$AT$4:$AT$33
Name TSPU_post_s: 'FMS'!$BD$4:$BD$33
Name RS_pre_s: 'FMS'!$AU$4:$AU$33
Name RS_post_s: 'FMS'!$BE$4:$BE$33

Sheet 안내
A1: H-IFIT 연구 원자료 입력 양식
A2: 12주 고강도 기능성 인터벌 트레이닝 × 대학 태권도 겨루기 선수 (VO2max · FMS)
A4: 목적
B5: 원자료로 포스터 수치를 다시 계산하고(특히 FMS 총점 평균과 t값이 서로 맞지 않는 문제), 통제군 기술통계·자유도·효과크기·95% CI·대상자 특성을 구해 원고의 표 1·3·4와 연구방법을 완성하기 위한 양식입니다.
A6: 가장 중요한 원칙
A7: ! | B7: 원 기록지·측정 출력물의 값을 그대로 입력하세요. 포스터 값과 달라도 원자료를 고치거나 대상자를 빼지 마세요. '다름'은 그대로 보고할 결과입니다. 입력 실수를 고쳤다면 '수정기록' 시트에 원래 값과 근거를 남깁니다.
A8: 작성 순서
A9: 1 연구정보 | B9: 배정·IRB·측정 장비·FMS 평가자 등에 답하고 근거(문서·기록 / 기억 / 모름)를 고릅니다.
A10: 2 대상자_VO2max | B10: 1명당 1행(4–33행). ID·집단·분석포함·인적사항·사전/사후 체중과 VO2max.
A11: 3 FMS | B11: ID를 직접 입력하고 하위항목 원점수를 입력합니다. 집단·분석포함은 ID로 자동 연결되므로 행 순서는 달라도 됩니다.
A12: 3b FMS_평가자2 | B12: (선택) 평가자가 2명이고 두 사람 점수를 따로 갖고 있으면 평가자2 점수를 입력합니다.
A13: 4 출석_훈련기록 | B13: 실험군 회기별 출석(1/0), 35행에는 전체 취소된 회기에만 0, 정규훈련 시간·강도(두 집단).
A14: 5 주차별_프로그램 | B14: 주차별 실제 운동 구성(종목·시간·세트·휴식).
A15: 6 대상자_흐름 | B15: 적격성 평가 → 배정 → 중단·추적 소실 → 결과별 분석 인원.
A16: 7 자동검산 | B16: 확인만 하면 됩니다. 결과는 기록용이며, 포스터 값과 같은지 다른지 표시됩니다.
A17: 색 구분
A18: 노란 칸 + 파란 글씨 | B18: 직접 입력하는 칸
A19: 회색 칸 | B19: 자동 계산 칸. 수정하거나 지우지 마세요.
A20: 연회색 기울임 (3행) | B20: 예시 행. 자료 범위 밖이라 분석에서 빠지므로 그대로 두셔도 됩니다.
A21: 주황 칸 | B21: 입력 점검 경고. 원 기록을 확인해 입력 실수면 고치고(수정기록에 기재), 기록과 같으면 그대로 둡니다.
A22: 파란 칸 (자동검산 H) | B22: 포스터 값과 다름. 오류 표시가 아니라 기록입니다.
A23: 코딩 규칙
A24: 집단 | B24: 1 = 실험군(H-IFIT), 2 = 통제군(정규훈련)
A25: 분석포함 | B25: 1 = 포함, 0 = 제외(제외 사유를 목록에서 고르고 상세를 적음). 빈칸은 제외로 처리되며 경고가 뜹니다. 탈락자도 행을 지우지 마세요.
A26: 결과별 포함 | B26: 대상자 시트의 분석포함은 VO2max에 적용되고 FMS에도 기본으로 따라갑니다. 결과마다 다르면(예: VO2max만 최대치 판정 미충족으로 제외) FMS 시트의 'FMS만 분석포함' 칸에 1/0을 따로 넣습니다.
A27: 성별 | B27: 1 = 남, 2 = 여
A28: FMS 약어 | B28: DS=Deep Squat, HS=Hurdle Step, ILL=In-line Lunge, SM=Shoulder Mobility, ASLR=Active Straight Leg Raise, TSPU=Trunk Stability Push-up, RS=Rotary Stability
A29: FMS 원점수 | B29: 0–3. 양측 항목(HS, ILL, SM, ASLR, RS)은 좌·우를 따로 입력하면 낮은 점수가 항목 점수가 됩니다. 동작 중 통증이 있었으면 그 원점수에 0을 입력합니다. 평가자 평균 등으로 소수라면 그대로 입력하세요(경고만 뜸).
A30: Clearing test | B30: 1 = 통증 있음 → 해당 항목 0점(SM←어깨 충돌, TSPU←척추 신전, RS←척추 굴곡; SM은 좌·우 중 한쪽이라도 통증이면 1), 0 = 없음. 검사하지 않았거나 기록이 없으면 빈칸(통증 없음으로 계산하고 자동검산 J에 개수 표시).
A31: FMS 총점만 있을 때 | B31: 하위항목이 없으면 '총점 기존 SPSS·포스터 값' 칸에만 넣어도 계산됩니다. 이 경우 검증이 아니라 재집계라는 점이 J에 표시됩니다.
A32: 결측값 | B32: 측정하지 않았거나 모르는 값은 반드시 빈칸. 0을 넣으면 실제 0으로 계산됩니다.
A33: 날짜 | B33: 2025-03-03처럼 하이픈으로 입력(2025.03.03은 날짜로 인식되지 않음).
A34: ID | B34: 실명 대신 코드(E01–E13, C01–C12 등). 같은 사람은 모든 시트에서 같은 ID.
A35: 행 관련 | B35: 자료 범위는 4–33행(30명)입니다. 행을 삽입·삭제하지 마세요. 정렬은 권하지 않습니다. 꼭 필요하면 4–33행만 선택한 뒤 [정렬] 대화상자에서 '머리글 포함'을 끄고 정렬하세요(1–3행이 섞이면 대상자가 분석에서 빠짐). FMS·출석 시트는 ID로 연결됩니다.
A36: 포스터 수치가 다르게 나올 수 있는 이유 (중립적 후보)
B37: 평가자 점수의 평균 사용, 좌우 점수를 평균·합산한 다른 채점 규칙, 실제 분석 인원 차이(탈락자), 다른 버전의 자료 파일, 공변량을 넣은 분석(ANCOVA), 포스터로 옮겨 적을 때의 전사 오류. 어느 것인지는 자료와 연구정보 답으로 확인합니다.
A38: Excel·SPSS
A39: Excel | B39: 파일을 열면 자동으로 계산됩니다. 위쪽에 '편집 사용' 버튼이 보이면 눌러야 계산 결과가 나타납니다.
A40: SPSS | B40: 1행이 SPSS 변수명입니다. 복사본에서 2·3행을 지우고, 불러올 때 범위를 마지막 대상자 행까지만 지정하세요(빈 행의 ""가 문자 변수로 읽힐 수 있음). 불러온 뒤 숫자 열이 문자형이면 ALTER TYPE d_vo2 pct_vo2 d_wt (F8.3). 처럼 바꿉니다. group_lbl, chk_vo2, chk_fms 같은 문자 열은 분석에서 빼세요.
A41: 보낼 것
...

Sheet 연구정보
A1: 연구 정보 (원고 '연구방법' 작성용)
A2: 노란 칸에 답하고, E열에 근거(문서·기록 / 기억 / 모름)를 고르세요. 모르면 '모름', 하지 않았으면 '미실시'라고 적어 주세요. 사실과 다른 답보다 '모름'이 훨씬 낫습니다. '기억'으로 표시한 답은 원고에 조심스럽게 쓰거나 투고 전에 기록으로 확인합니다.
A4: 번호 | B4: 확인 항목 | C4: 입력 (답변) | D4: 왜 필요한가 | E4: 근거
A5: A. 설계·배정
A6: A1 | B6: 무작위 배정을 했는가 (예 / 아니오) | D6: 예=무작위 대조시험(CONSORT), 아니오=비무작위 대조연구(TREND)
A7: A2 | B7: 배정 단위 (개인 / 팀·학교) | D7: 팀 단위면 군집 구조를 분석·기술해야 함
A8: A3 | B8: 무작위라면 방법 (난수표·제비뽑기·블록/층화 여부), 배정한 사람, 배정 은폐 방법 | D8: CONSORT 필수 항목
A9: A4 | B9: 무작위가 아니라면 배정 기준 (자원, 지도자 지정, 소속 팀 등) | D9: 선택편향 논의
A10: A5 | B10: 측정자 눈가림 여부 (VO2max·FMS 측정자가 집단을 알았는가) | D10: 측정 편향 대응
A11: A6 | B11: 연구계획서·분석계획 문서가 있는가, 작성 시점 (자료 수집 전/후), 일차·이차 결과변수와 가설 | D11: 결과를 보고 가설을 세웠다는 의심 방지
A12: A7 | B12: 임상연구 등록 여부, 등록처 (CRIS 등), 등록번호, 등록일 (미등록이면 '미등록') | D12: CONSORT·TREND 보고 항목
A13: B. 대상자
A14: B1 | B14: 소속 기관·팀 (익명 가능: 예) 경기도 소재 A대학 태권도부) | D14: 대상 기술
A15: B2 | B15: 모집 기간, 중재 시작일과 종료일 | D15: 중재 시점·시합 일정 확인
A16: B3 | B16: 선정 기준 (예: 경력 5년 이상, 최근 6개월 부상 없음) | D16: 필수
A17: B4 | B17: 제외 기준 | D17: 필수
A18: B5 | B18: 표본수 산출 근거 (G*Power: 효과크기 f, α, 검정력, 산출 인원). 사전에 하지 않았으면 '사전 산출 없음' | D18: 심사 단골 지적. 사후에 맞춰 만들지 않음
A19: B6 | B19: 시즌 구분 (시합기 / 준비기 / 비시즌)과 중재 기간 중 출전한 대회 | D19: 교란변수
A20: C. 연구윤리
A21: C1 | B21: IRB 심의 상태 (승인 / 면제 / 심의 받지 않음)와 심의 기관명 | D21: 사실대로 기재. 사후 승인이면 사후 승인으로 표기
A22: C2 | B22: IRB 승인번호, 승인일. 승인일이 첫 사전 측정일보다 앞서는가 | D22: 본문 기재 사항
A23: C3 | B23: 서면 동의 취득 여부 (미성년자 포함 시 보호자 동의) | D23: 필수
A24: C4 | B24: 개인정보 보호 방법 (코드화, 자료 보관자·장소·기간) | D24: 연구윤리 기술
A25: C5 | B25: 중재 중 안전관리 (사전 건강 확인, 현장 인원, 운동 중단 기준) | D25: 고강도 중재의 안전성 기술
A26: D. 중재·비교조건
A27: D1 | B27: 실험군은 정규훈련에 H-IFIT를 '추가'했는가, 정규훈련 일부를 H-IFIT로 '대체'했는가 | D27: 핵심: 두 집단 총 운동량 차이
A28: D2 | B28: 통제군 정규훈련 내용 (겨루기·기술·체력 등 구성) | D28: 비교조건 기술
A29: D3 | B29: 정규훈련 주당 횟수·시간·강도(RPE 등): 두 집단 각각, 중재 기간 중 | D29: 총 훈련량 비교
A30: D4 | B30: H-IFIT 지도자 (자격·경력), 장소, 장비 | D30: 재현성
A31: D5 | B31: HRmax 산출 방법 (검사 실측 / 220−연령 / 기타), 심박 측정 장비 모델, 심박 기록 회기 | D31: 강도 보고
A32: D6 | B32: RPE 척도 (Borg 6–20 / CR-10)와 수집 시점 (회기 종료 후 몇 분) | D32: 강도 보고
A33: D7 | B33: 주차별 진행(점증) 기준 (예: 4주마다 운동:휴식 비율 변경) | D33: 주차별_프로그램 시트와 함께
A34: D8 | B34: 두 집단의 중재 기간 중 부상·이상반응 (없으면 '없음, 기록 있음' / '기록 없음' 구분) | D34: 위해 보고
A35: D9 | B35: '본운동 40분'에 휴식·세트 간 휴식·전환 시간이 포함되는가 | D35: 포스터 범위(6–10종목·3–4세트)와 40분의 정합성
A36: D10 | B36: 12개 운동 중 회기별 6–10개를 고른 기준과 실시 순서 | D36: 재현성
A37: D11 | B37: 수면·영양·개인 추가훈련 통제 여부 (두 집단) | D37: 교란변수
A38: E. VO2max 측정
A39: E1 | B39: 트레드밀 제조사·모델 | D39: 필수
A40: E2 | B40: 호흡가스 분석기 제조사·모델 (직접 측정인지, 추정식인지) | D40: 직접 측정이 아니면 '추정 VO2max'로 표기
A41: E3 | B41: 가스분석기 보정 절차 (매 검사 전 가스·유량 보정 등) | D41: 측정 신뢰도
...

Sheet 대상자_VO2max
A1: ID | B1: group | C1: group_lbl | D1: include | E1: excl_reason | F1: excl_detail | G1: team | H1: sex | I1: age | J1: height | K1: wclass | L1: career | M1: level | N1: wt_pre | O1: vo2_pre | P1: vo2abs_pre | Q1: hrmax_pre | R1: rer_pre | S1: rpe_pre | T1: plateau_pre | U1: crit_pre | V1: date_pre | W1: wt_post | X1: vo2_post | Y1: vo2abs_post | Z1: hrmax_post | AA1: rer_post | AB1: rpe_post | AC1: plateau_post | AD1: crit_post | AE1: date_post | AF1: d_vo2 | AG1: pct_vo2 | AH1: d_wt | AI1: critn_pre | AJ1: critn_post | AK1: chk_vo2
A2: 대상자 ID (예: E01, C01) | B2: 집단 1=실험 2=통제 | C2: 집단명 (자동) | D2: 분석 포함 1=포함 0=제외 (FMS는 기본값) | E2: 제외 사유 (목록 선택) | F2: 제외 사유 상세 | G2: 소속 팀· 대학 코드 | H2: 성별 1=남 2=여 | I2: 연령 (만, 세) | J2: 신장 (cm) | K2: 체급 (예: -68kg) | L2: 선수 경력 (년) | M2: 등록 수준·단· 주요 입상 | N2: 사전 체중 (kg) | O2: 사전 VO2max (mL/kg/min) | P2: 사전 VO2max 절대값 (mL/min) | Q2: 사전 검사 최고심박 (bpm) | R2: 사전 검사 최고 RER | S2: 사전 검사 종료 RPE (6–20) | T2: 사전 VO2 plateau 1=예 0=아니오 | U2: 사전 최대치 판정 충족 1=예 0=아니오 | V2: 사전 VO2max 검사일 (YYYY-MM-DD) | W2: 사후 체중 (kg) | X2: 사후 VO2max (mL/kg/min) | Y2: 사후 VO2max 절대값 (mL/min) | Z2: 사후 검사 최고심박 (bpm) | AA2: 사후 검사 최고 RER | AB2: 사후 검사 종료 RPE (6–20) | AC2: 사후 VO2 plateau 1=예 0=아니오 | AD2: 사후 최대치 판정 충족 1=예 0=아니오 | AE2: 사후 VO2max 검사일 (YYYY-MM-DD) | AF2: VO2max 변화 사후−사전 (자동) | AG2: VO2max 변화율 (자동) | AH2: 체중 변화 (kg, 자동) | AI2: 사전 충족 기준 수 (0–4, 자동) | AJ2: 사후 충족 기준 수 (0–4, 자동) | AK2: 자동 점검 (경고가 있으면 주황색)
A3: 예시 | B3: 1 | C3: =IF(B3="","",IF(B3=1,"실험군",IF(B3=2,"통제군","코드오류"))) | D3: 0 | E3: 기타 | F3: 예시 행(분석 제외) | G3: A대 | H3: 1 | I3: 20 | J3: 176.4 | K3: -68kg | L3: 8.5 | M3: 대학부 등록, 3단 | N3: 68.2 | O3: 48.3 | P3: 3294 | Q3: 196 | R3: 1.15 | S3: 19 | T3: 1 | U3: 1 | V3: 45719 | W3: 67.5 | X3: 52.4 | Y3: 3537 | Z3: 195 | AA3: 1.13 | AB3: 19 | AC3: 0 | AD3: 1 | AE3: 45807 | AF3: =IF(AND(ISNUMBER(O3),ISNUMBER(X3)),X3-O3,"") | AG3: =IF(AND(ISNUMBER(O3),ISNUMBER(X3)),IF(O3<>0,(X3-O3)/O3,""),"") | AH3: =IF(AND(ISNUMBER(N3),ISNUMBER(W3)),W3-N3,"") | AI3: =IF(COUNT(R3,Q3,S3,T3)=0,"",IF(ISNUMBER(R3),--(R3>=1.1),0)+IF(AND(ISNUMBER(Q3),ISNUMBER(I3)),--(Q3>=0.95*(220-I3)),0)+IF(ISNUMBER(S3),--(S3>=17),0)+IF(ISNUMBER(T3),--(T3=1),0)) | AJ3: =IF(COUNT(AA3,Z3,AB3,AC3)=0,"",IF(ISNUMBER(AA3),--(AA3>=1.1),0)+IF(AND(ISNUMBER(Z3),ISNUMBER(I3)),--(Z3>=0.95*(220-I3)),0)+IF(ISNUMBER(AB3),--(AB3>=17),0)+IF(ISNUMBER(AC3),--(AC3=1),0)) | AK3: =IF(A3="","",TRIM(IF(COUNTIF($A$4:$A$33,A3)>1,"ID 중복 ","")&IF(LEN(A3)<>LEN(TRIM(A3)),"ID 앞뒤 공백 ","")&IF(AND(B3<>1,B3<>2),"집단코드 확인 ","")&IF(OR(D3="",AND(D3<>0,D3<>1)),"분석포함 코드 확인(빈칸=제외됨) ","")&IF(AND(ISNUMBER(D3),D3=0,E3=""),"제외 사유 없음 ","")&IF(AND(O3<>"",NOT(ISNUMBER(O3))),"사전VO2 숫자 아님 ","")&IF(AND(X3<>"",NOT(ISNUMBER(X3))),"사후VO2 숫자 아님 ","")&IF(AND(N3<>"",NOT(ISNUMBER(N3))),"사전체중 숫자 아님 ","")&IF(AND(W3<>"",NOT(ISNUMBER(W3))),"사후체중 숫자 아님 ","")&IF(ISNUMBER(O3),IF(OR(O3<25,O3>85),"사전VO2 범위(25–85) 확인 ",""),"")&IF(ISNUMBER(X3),IF(OR(X3<25,X3>85),"사후VO2 범위(25–85) 확인 ",""),"")&IF(AND(ISNUMBER(O3),ISNUMBER(X3)),IF(ABS(X3-O3)>12,"VO2 변화량 12 초과 확인 ",""),"")&IF(AND(ISNUMBER(P3),ISNUMBER(N3),ISNUMBER(O3)),IF(N3<=0,"사전 체중 확인 ",IF(ABS(P3/N3-O3)>0.5,"사전 절대값/체중≠상대값 ","")),"")&IF(AND(ISNUMBER(Y3),ISNUMBER(W3),ISNUMBER(X3)),IF(W3<=0,"사후 체중 확인 ",IF(ABS(Y3/W3-X3)>0.5,"사후 절대값/체중≠상대값 ","")),"")&IF(ISNUMBER(R3),IF(OR(R3<0.85,R3>1.5),"사전 RER 범위 확인 ",""),"")&IF(ISNUMBER(AA3),IF(OR(AA3<0.85,AA3>1.5),"사후 RER 범위 확인 ",""),"")&IF(ISNUMBER(Q3),IF(OR(Q3<150,Q3>225),"사전 최고심박 범위 확인 ",""),"")&IF(ISNUMBER(Z3),IF(OR(Z3<150,Z3>225),"사후 최고심박 범위 확인 ",""),"")&IF(AND(ISNUMBER(U3),ISNUMBER(AI3)),IF(AND(U3=1,AI3<2),"사전 판정충족=1이나 기준 2개 미만 ",""),"")&IF(AND(ISNUMBER(AD3),ISNUMBER(AJ3)),IF(AND(AD3=1,AJ3<2),"사후 판정충족=1이나 기준 2개 미만 ",""),"")&IF(AND(V3<>"",NOT(ISNUMBER(V3))),"사전 검사일 날짜형식 아님 ","")&IF(AND(AE3<>"",NOT(ISNUMBER(AE3))),"사후 검사일 날짜형식 아님 ","")&IF(AND(ISNUMBER(V3),ISNUMBER(AE3)),IF(AE3<=V3,"검사일 역전 ",IF(OR(AE3-V3<77,AE3-V3>126),"사전–사후 간격(11–18주) 확인 ","")),"")&IF(D3=1,IF(OR(NOT(ISNUMBER(O3)),NOT(ISNUMBER(X3))),"분석포함인데 VO2 결측 ",""),"")))
C4: =IF(B4="","",IF(B4=1,"실험군",IF(B4=2,"통제군","코드오류"))) | AF4: =IF(AND(ISNUMBER(O4),ISNUMBER(X4)),X4-O4,"") | AG4: =IF(AND(ISNUMBER(O4),ISNUMBER(X4)),IF(O4<>0,(X4-O4)/O4,""),"") | AH4: =IF(AND(ISNUMBER(N4),ISNUMBER(W4)),W4-N4,"") | AI4: =IF(COUNT(R4,Q4,S4,T4)=0,"",IF(ISNUMBER(R4),--(R4>=1.1),0)+IF(AND(ISNUMBER(Q4),ISNUMBER(I4)),--(Q4>=0.95*(220-I4)),0)+IF(ISNUMBER(S4),--(S4>=17),0)+IF(ISNUMBER(T4),--(T4=1),0)) | AJ4: =IF(COUNT(AA4,Z4,AB4,AC4)=0,"",IF(ISNUMBER(AA4),--(AA4>=1.1),0)+IF(AND(ISNUMBER(Z4),ISNUMBER(I4)),--(Z4>=0.95*(220-I4)),0)+IF(ISNUMBER(AB4),--(AB4>=17),0)+IF(ISNUMBER(AC4),--(AC4=1),0)) | AK4: =IF(A4="","",TRIM(IF(COUNTIF($A$4:$A$33,A4)>1,"ID 중복 ","")&IF(LEN(A4)<>LEN(TRIM(A4)),"ID 앞뒤 공백 ","")&IF(AND(B4<>1,B4<>2),"집단코드 확인 ","")&IF(OR(D4="",AND(D4<>0,D4<>1)),"분석포함 코드 확인(빈칸=제외됨) ","")&IF(AND(ISNUMBER(D4),D4=0,E4=""),"제외 사유 없음 ","")&IF(AND(O4<>"",NOT(ISNUMBER(O4))),"사전VO2 숫자 아님 ","")&IF(AND(X4<>"",NOT(ISNUMBER(X4))),"사후VO2 숫자 아님 ","")&IF(AND(N4<>"",NOT(ISNUMBER(N4))),"사전체중 숫자 아님 ","")&IF(AND(W4<>"",NOT(ISNUMBER(W4))),"사후체중 숫자 아님 ","")&IF(ISNUMBER(O4),IF(OR(O4<25,O4>85),"사전VO2 범위(25–85) 확인 ",""),"")&IF(ISNUMBER(X4),IF(OR(X4<25,X4>85),"사후VO2 범위(25–85) 확인 ",""),"")&IF(AND(ISNUMBER(O4),ISNUMBER(X4)),IF(ABS(X4-O4)>12,"VO2 변화량 12 초과 확인 ",""),"")&IF(AND(ISNUMBER(P4),ISNUMBER(N4),ISNUMBER(O4)),IF(N4<=0,"사전 체중 확인 ",IF(ABS(P4/N4-O4)>0.5,"사전 절대값/체중≠상대값 ","")),"")&IF(AND(ISNUMBER(Y4),ISNUMBER(W4),ISNUMBER(X4)),IF(W4<=0,"사후 체중 확인 ",IF(ABS(Y4/W4-X4)>0.5,"사후 절대값/체중≠상대값 ","")),"")&IF(ISNUMBER(R4),IF(OR(R4<0.85,R4>1.5),"사전 RER 범위 확인 ",""),"")&IF(ISNUMBER(AA4),IF(OR(AA4<0.85,AA4>1.5),"사후 RER 범위 확인 ",""),"")&IF(ISNUMBER(Q4),IF(OR(Q4<150,Q4>225),"사전 최고심박 범위 확인 ",""),"")&IF(ISNUMBER(Z4),IF(OR(Z4<150,Z4>225),"사후 최고심박 범위 확인 ",""),"")&IF(AND(ISNUMBER(U4),ISNUMBER(AI4)),IF(AND(U4=1,AI4<2),"사전 판정충족=1이나 기준 2개 미만 ",""),"")&IF(AND(ISNUMBER(AD4),ISNUMBER(AJ4)),IF(AND(AD4=1,AJ4<2),"사후 판정충족=1이나 기준 2개 미만 ",""),"")&IF(AND(V4<>"",NOT(ISNUMBER(V4))),"사전 검사일 날짜형식 아님 ","")&IF(AND(AE4<>"",NOT(ISNUMBER(AE4))),"사후 검사일 날짜형식 아님 ","")&IF(AND(ISNUMBER(V4),ISNUMBER(AE4)),IF(AE4<=V4,"검사일 역전 ",IF(OR(AE4-V4<77,AE4-V4>126),"사전–사후 간격(11–18주) 확인 ","")),"")&IF(D4=1,IF(OR(NOT(ISNUMBER(O4)),NOT(ISNUMBER(X4))),"분석포함인데 VO2 결측 ",""),"")))
C5: =IF(B5="","",IF(B5=1,"실험군",IF(B5=2,"통제군","코드오류"))) | AF5: =IF(AND(ISNUMBER(O5),ISNUMBER(X5)),X5-O5,"") | AG5: =IF(AND(ISNUMBER(O5),ISNUMBER(X5)),IF(O5<>0,(X5-O5)/O5,""),"") | AH5: =IF(AND(ISNUMBER(N5),ISNUMBER(W5)),W5-N5,"") | AI5: =IF(COUNT(R5,Q5,S5,T5)=0,"",IF(ISNUMBER(R5),--(R5>=1.1),0)+IF(AND(ISNUMBER(Q5),ISNUMBER(I5)),--(Q5>=0.95*(220-I5)),0)+IF(ISNUMBER(S5),--(S5>=17),0)+IF(ISNUMBER(T5),--(T5=1),0)) | AJ5: =IF(COUNT(AA5,Z5,AB5,AC5)=0,"",IF(ISNUMBER(AA5),--(AA5>=1.1),0)+IF(AND(ISNUMBER(Z5),ISNUMBER(I5)),--(Z5>=0.95*(220-I5)),0)+IF(ISNUMBER(AB5),--(AB5>=17),0)+IF(ISNUMBER(AC5),--(AC5=1),0)) | AK5: =IF(A5="","",TRIM(IF(COUNTIF($A$4:$A$33,A5)>1,"ID 중복 ","")&IF(LEN(A5)<>LEN(TRIM(A5)),"ID 앞뒤 공백 ","")&IF(AND(B5<>1,B5<>2),"집단코드 확인 ","")&IF(OR(D5="",AND(D5<>0,D5<>1)),"분석포함 코드 확인(빈칸=제외됨) ","")&IF(AND(ISNUMBER(D5),D5=0,E5=""),"제외 사유 없음 ","")&IF(AND(O5<>"",NOT(ISNUMBER(O5))),"사전VO2 숫자 아님 ","")&IF(AND(X5<>"",NOT(ISNUMBER(X5))),"사후VO2 숫자 아님 ","")&IF(AND(N5<>"",NOT(ISNUMBER(N5))),"사전체중 숫자 아님 ","")&IF(AND(W5<>"",NOT(ISNUMBER(W5))),"사후체중 숫자 아님 ","")&IF(ISNUMBER(O5),IF(OR(O5<25,O5>85),"사전VO2 범위(25–85) 확인 ",""),"")&IF(ISNUMBER(X5),IF(OR(X5<25,X5>85),"사후VO2 범위(25–85) 확인 ",""),"")&IF(AND(ISNUMBER(O5),ISNUMBER(X5)),IF(ABS(X5-O5)>12,"VO2 변화량 12 초과 확인 ",""),"")&IF(AND(ISNUMBER(P5),ISNUMBER(N5),ISNUMBER(O5)),IF(N5<=0,"사전 체중 확인 ",IF(ABS(P5/N5-O5)>0.5,"사전 절대값/체중≠상대값 ","")),"")&IF(AND(ISNUMBER(Y5),ISNUMBER(W5),ISNUMBER(X5)),IF(W5<=0,"사후 체중 확인 ",IF(ABS(Y5/W5-X5)>0.5,"사후 절대값/체중≠상대값 ","")),"")&IF(ISNUMBER(R5),IF(OR(R5<0.85,R5>1.5),"사전 RER 범위 확인 ",""),"")&IF(ISNUMBER(AA5),IF(OR(AA5<0.85,AA5>1.5),"사후 RER 범위 확인 ",""),"")&IF(ISNUMBER(Q5),IF(OR(Q5<150,Q5>225),"사전 최고심박 범위 확인 ",""),"")&IF(ISNUMBER(Z5),IF(OR(Z5<150,Z5>225),"사후 최고심박 범위 확인 ",""),"")&IF(AND(ISNUMBER(U5),ISNUMBER(AI5)),IF(AND(U5=1,AI5<2),"사전 판정충족=1이나 기준 2개 미만 ",""),"")&IF(AND(ISNUMBER(AD5),ISNUMBER(AJ5)),IF(AND(AD5=1,AJ5<2),"사후 판정충족=1이나 기준 2개 미만 ",""),"")&IF(AND(V5<>"",NOT(ISNUMBER(V5))),"사전 검사일 날짜형식 아님 ","")&IF(AND(AE5<>"",NOT(ISNUMBER(AE5))),"사후 검사일 날짜형식 아님 ","")&IF(AND(ISNUMBER(V5),ISNUMBER(AE5)),IF(AE5<=V5,"검사일 역전 ",IF(OR(AE5-V5<77,AE5-V5>126),"사전–사후 간격(11–18주) 확인 ","")),"")&IF(D5=1,IF(OR(NOT(ISNUMBER(O5)),NOT(ISNUMBER(X5))),"분석포함인데 VO2 결측 ",""),"")))
C6: =IF(B6="","",IF(B6=1,"실험군",IF(B6=2,"통제군","코드오류"))) | AF6: =IF(AND(ISNUMBER(O6),ISNUMBER(X6)),X6-O6,"") | AG6: =IF(AND(ISNUMBER(O6),ISNUMBER(X6)),IF(O6<>0,(X6-O6)/O6,""),"") | AH6: =IF(AND(ISNUMBER(N6),ISNUMBER(W6)),W6-N6,"") | AI6: =IF(COUNT(R6,Q6,S6,T6)=0,"",IF(ISNUMBER(R6),--(R6>=1.1),0)+IF(AND(ISNUMBER(Q6),ISNUMBER(I6)),--(Q6>=0.95*(220-I6)),0)+IF(ISNUMBER(S6),--(S6>=17),0)+IF(ISNUMBER(T6),--(T6=1),0)) | AJ6: =IF(COUNT(AA6,Z6,AB6,AC6)=0,"",IF(ISNUMBER(AA6),--(AA6>=1.1),0)+IF(AND(ISNUMBER(Z6),ISNUMBER(I6)),--(Z6>=0.95*(220-I6)),0)+IF(ISNUMBER(AB6),--(AB6>=17),0)+IF(ISNUMBER(AC6),--(AC6=1),0)) | AK6: =IF(A6="","",TRIM(IF(COUNTIF($A$4:$A$33,A6)>1,"ID 중복 ","")&IF(LEN(A6)<>LEN(TRIM(A6)),"ID 앞뒤 공백 ","")&IF(AND(B6<>1,B6<>2),"집단코드 확인 ","")&IF(OR(D6="",AND(D6<>0,D6<>1)),"분석포함 코드 확인(빈칸=제외됨) ","")&IF(AND(ISNUMBER(D6),D6=0,E6=""),"제외 사유 없음 ","")&IF(AND(O6<>"",NOT(ISNUMBER(O6))),"사전VO2 숫자 아님 ","")&IF(AND(X6<>"",NOT(ISNUMBER(X6))),"사후VO2 숫자 아님 ","")&IF(AND(N6<>"",NOT(ISNUMBER(N6))),"사전체중 숫자 아님 ","")&IF(AND(W6<>"",NOT(ISNUMBER(W6))),"사후체중 숫자 아님 ","")&IF(ISNUMBER(O6),IF(OR(O6<25,O6>85),"사전VO2 범위(25–85) 확인 ",""),"")&IF(ISNUMBER(X6),IF(OR(X6<25,X6>85),"사후VO2 범위(25–85) 확인 ",""),"")&IF(AND(ISNUMBER(O6),ISNUMBER(X6)),IF(ABS(X6-O6)>12,"VO2 변화량 12 초과 확인 ",""),"")&IF(AND(ISNUMBER(P6),ISNUMBER(N6),ISNUMBER(O6)),IF(N6<=0,"사전 체중 확인 ",IF(ABS(P6/N6-O6)>0.5,"사전 절대값/체중≠상대값 ","")),"")&IF(AND(ISNUMBER(Y6),ISNUMBER(W6),ISNUMBER(X6)),IF(W6<=0,"사후 체중 확인 ",IF(ABS(Y6/W6-X6)>0.5,"사후 절대값/체중≠상대값 ","")),"")&IF(ISNUMBER(R6),IF(OR(R6<0.85,R6>1.5),"사전 RER 범위 확인 ",""),"")&IF(ISNUMBER(AA6),IF(OR(AA6<0.85,AA6>1.5),"사후 RER 범위 확인 ",""),"")&IF(ISNUMBER(Q6),IF(OR(Q6<150,Q6>225),"사전 최고심박 범위 확인 ",""),"")&IF(ISNUMBER(Z6),IF(OR(Z6<150,Z6>225),"사후 최고심박 범위 확인 ",""),"")&IF(AND(ISNUMBER(U6),ISNUMBER(AI6)),IF(AND(U6=1,AI6<2),"사전 판정충족=1이나 기준 2개 미만 ",""),"")&IF(AND(ISNUMBER(AD6),ISNUMBER(AJ6)),IF(AND(AD6=1,AJ6<2),"사후 판정충족=1이나 기준 2개 미만 ",""),"")&IF(AND(V6<>"",NOT(ISNUMBER(V6))),"사전 검사일 날짜형식 아님 ","")&IF(AND(AE6<>"",NOT(ISNUMBER(AE6))),"사후 검사일 날짜형식 아님 ","")&IF(AND(ISNUMBER(V6),ISNUMBER(AE6)),IF(AE6<=V6,"검사일 역전 ",IF(OR(AE6-V6<77,AE6-V6>126),"사전–사후 간격(11–18주) 확인 ","")),"")&IF(D6=1,IF(OR(NOT(ISNUMBER(O6)),NOT(ISNUMBER(X6))),"분석포함인데 VO2 결측 ",""),"")))
C7: =IF(B7="","",IF(B7=1,"실험군",IF(B7=2,"통제군","코드오류"))) | AF7: =IF(AND(ISNUMBER(O7),ISNUMBER(X7)),X7-O7,"") | AG7: =IF(AND(ISNUMBER(O7),ISNUMBER(X7)),IF(O7<>0,(X7-O7)/O7,""),"") | AH7: =IF(AND(ISNUMBER(N7),ISNUMBER(W7)),W7-N7,"") | AI7: =IF(COUNT(R7,Q7,S7,T7)=0,"",IF(ISNUMBER(R7),--(R7>=1.1),0)+IF(AND(ISNUMBER(Q7),ISNUMBER(I7)),--(Q7>=0.95*(220-I7)),0)+IF(ISNUMBER(S7),--(S7>=17),0)+IF(ISNUMBER(T7),--(T7=1),0)) | AJ7: =IF(COUNT(AA7,Z7,AB7,AC7)=0,"",IF(ISNUMBER(AA7),--(AA7>=1.1),0)+IF(AND(ISNUMBER(Z7),ISNUMBER(I7)),--(Z7>=0.95*(220-I7)),0)+IF(ISNUMBER(AB7),--(AB7>=17),0)+IF(ISNUMBER(AC7),--(AC7=1),0)) | AK7: =IF(A7="","",TRIM(IF(COUNTIF($A$4:$A$33,A7)>1,"ID 중복 ","")&IF(LEN(A7)<>LEN(TRIM(A7)),"ID 앞뒤 공백 ","")&IF(AND(B7<>1,B7<>2),"집단코드 확인 ","")&IF(OR(D7="",AND(D7<>0,D7<>1)),"분석포함 코드 확인(빈칸=제외됨) ","")&IF(AND(ISNUMBER(D7),D7=0,E7=""),"제외 사유 없음 ","")&IF(AND(O7<>"",NOT(ISNUMBER(O7))),"사전VO2 숫자 아님 ","")&IF(AND(X7<>"",NOT(ISNUMBER(X7))),"사후VO2 숫자 아님 ","")&IF(AND(N7<>"",NOT(ISNUMBER(N7))),"사전체중 숫자 아님 ","")&IF(AND(W7<>"",NOT(ISNUMBER(W7))),"사후체중 숫자 아님 ","")&IF(ISNUMBER(O7),IF(OR(O7<25,O7>85),"사전VO2 범위(25–85) 확인 ",""),"")&IF(ISNUMBER(X7),IF(OR(X7<25,X7>85),"사후VO2 범위(25–85) 확인 ",""),"")&IF(AND(ISNUMBER(O7),ISNUMBER(X7)),IF(ABS(X7-O7)>12,"VO2 변화량 12 초과 확인 ",""),"")&IF(AND(ISNUMBER(P7),ISNUMBER(N7),ISNUMBER(O7)),IF(N7<=0,"사전 체중 확인 ",IF(ABS(P7/N7-O7)>0.5,"사전 절대값/체중≠상대값 ","")),"")&IF(AND(ISNUMBER(Y7),ISNUMBER(W7),ISNUMBER(X7)),IF(W7<=0,"사후 체중 확인 ",IF(ABS(Y7/W7-X7)>0.5,"사후 절대값/체중≠상대값 ","")),"")&IF(ISNUMBER(R7),IF(OR(R7<0.85,R7>1.5),"사전 RER 범위 확인 ",""),"")&IF(ISNUMBER(AA7),IF(OR(AA7<0.85,AA7>1.5),"사후 RER 범위 확인 ",""),"")&IF(ISNUMBER(Q7),IF(OR(Q7<150,Q7>225),"사전 최고심박 범위 확인 ",""),"")&IF(ISNUMBER(Z7),IF(OR(Z7<150,Z7>225),"사후 최고심박 범위 확인 ",""),"")&IF(AND(ISNUMBER(U7),ISNUMBER(AI7)),IF(AND(U7=1,AI7<2),"사전 판정충족=1이나 기준 2개 미만 ",""),"")&IF(AND(ISNUMBER(AD7),ISNUMBER(AJ7)),IF(AND(AD7=1,AJ7<2),"사후 판정충족=1이나 기준 2개 미만 ",""),"")&IF(AND(V7<>"",NOT(ISNUMBER(V7))),"사전 검사일 날짜형식 아님 ","")&IF(AND(AE7<>"",NOT(ISNUMBER(AE7))),"사후 검사일 날짜형식 아님 ","")&IF(AND(ISNUMBER(V7),ISNUMBER(AE7)),IF(AE7<=V7,"검사일 역전 ",IF(OR(AE7-V7<77,AE7-V7>126),"사전–사후 간격(11–18주) 확인 ","")),"")&IF(D7=1,IF(OR(NOT(ISNUMBER(O7)),NOT(ISNUMBER(X7))),"분석포함인데 VO2 결측 ",""),"")))
C8: =IF(B8="","",IF(B8=1,"실험군",IF(B8=2,"통제군","코드오류"))) | AF8: =IF(AND(ISNUMBER(O8),ISNUMBER(X8)),X8-O8,"") | AG8: =IF(AND(ISNUMBER(O8),ISNUMBER(X8)),IF(O8<>0,(X8-O8)/O8,""),"") | AH8: =IF(AND(ISNUMBER(N8),ISNUMBER(W8)),W8-N8,"") | AI8: =IF(COUNT(R8,Q8,S8,T8)=0,"",IF(ISNUMBER(R8),--(R8>=1.1),0)+IF(AND(ISNUMBER(Q8),ISNUMBER(I8)),--(Q8>=0.95*(220-I8)),0)+IF(ISNUMBER(S8),--(S8>=17),0)+IF(ISNUMBER(T8),--(T8=1),0)) | AJ8: =IF(COUNT(AA8,Z8,AB8,AC8)=0,"",IF(ISNUMBER(AA8),--(AA8>=1.1),0)+IF(AND(ISNUMBER(Z8),ISNUMBER(I8)),--(Z8>=0.95*(220-I8)),0)+IF(ISNUMBER(AB8),--(AB8>=17),0)+IF(ISNUMBER(AC8),--(AC8=1),0)) | AK8: =IF(A8="","",TRIM(IF(COUNTIF($A$4:$A$33,A8)>1,"ID 중복 ","")&IF(LEN(A8)<>LEN(TRIM(A8)),"ID 앞뒤 공백 ","")&IF(AND(B8<>1,B8<>2),"집단코드 확인 ","")&IF(OR(D8="",AND(D8<>0,D8<>1)),"분석포함 코드 확인(빈칸=제외됨) ","")&IF(AND(ISNUMBER(D8),D8=0,E8=""),"제외 사유 없음 ","")&IF(AND(O8<>"",NOT(ISNUMBER(O8))),"사전VO2 숫자 아님 ","")&IF(AND(X8<>"",NOT(ISNUMBER(X8))),"사후VO2 숫자 아님 ","")&IF(AND(N8<>"",NOT(ISNUMBER(N8))),"사전체중 숫자 아님 ","")&IF(AND(W8<>"",NOT(ISNUMBER(W8))),"사후체중 숫자 아님 ","")&IF(ISNUMBER(O8),IF(OR(O8<25,O8>85),"사전VO2 범위(25–85) 확인 ",""),"")&IF(ISNUMBER(X8),IF(OR(X8<25,X8>85),"사후VO2 범위(25–85) 확인 ",""),"")&IF(AND(ISNUMBER(O8),ISNUMBER(X8)),IF(ABS(X8-O8)>12,"VO2 변화량 12 초과 확인 ",""),"")&IF(AND(ISNUMBER(P8),ISNUMBER(N8),ISNUMBER(O8)),IF(N8<=0,"사전 체중 확인 ",IF(ABS(P8/N8-O8)>0.5,"사전 절대값/체중≠상대값 ","")),"")&IF(AND(ISNUMBER(Y8),ISNUMBER(W8),ISNUMBER(X8)),IF(W8<=0,"사후 체중 확인 ",IF(ABS(Y8/W8-X8)>0.5,"사후 절대값/체중≠상대값 ","")),"")&IF(ISNUMBER(R8),IF(OR(R8<0.85,R8>1.5),"사전 RER 범위 확인 ",""),"")&IF(ISNUMBER(AA8),IF(OR(AA8<0.85,AA8>1.5),"사후 RER 범위 확인 ",""),"")&IF(ISNUMBER(Q8),IF(OR(Q8<150,Q8>225),"사전 최고심박 범위 확인 ",""),"")&IF(ISNUMBER(Z8),IF(OR(Z8<150,Z8>225),"사후 최고심박 범위 확인 ",""),"")&IF(AND(ISNUMBER(U8),ISNUMBER(AI8)),IF(AND(U8=1,AI8<2),"사전 판정충족=1이나 기준 2개 미만 ",""),"")&IF(AND(ISNUMBER(AD8),ISNUMBER(AJ8)),IF(AND(AD8=1,AJ8<2),"사후 판정충족=1이나 기준 2개 미만 ",""),"")&IF(AND(V8<>"",NOT(ISNUMBER(V8))),"사전 검사일 날짜형식 아님 ","")&IF(AND(AE8<>"",NOT(ISNUMBER(AE8))),"사후 검사일 날짜형식 아님 ","")&IF(AND(ISNUMBER(V8),ISNUMBER(AE8)),IF(AE8<=V8,"검사일 역전 ",IF(OR(AE8-V8<77,AE8-V8>126),"사전–사후 간격(11–18주) 확인 ","")),"")&IF(D8=1,IF(OR(NOT(ISNUMBER(O8)),NOT(ISNUMBER(X8))),"분석포함인데 VO2 결측 ",""),"")))
C9: =IF(B9="","",IF(B9=1,"실험군",IF(B9=2,"통제군","코드오류"))) | AF9: =IF(AND(ISNUMBER(O9),ISNUMBER(X9)),X9-O9,"") | AG9: =IF(AND(ISNUMBER(O9),ISNUMBER(X9)),IF(O9<>0,(X9-O9)/O9,""),"") | AH9: =IF(AND(ISNUMBER(N9),ISNUMBER(W9)),W9-N9,"") | AI9: =IF(COUNT(R9,Q9,S9,T9)=0,"",IF(ISNUMBER(R9),--(R9>=1.1),0)+IF(AND(ISNUMBER(Q9),ISNUMBER(I9)),--(Q9>=0.95*(220-I9)),0)+IF(ISNUMBER(S9),--(S9>=17),0)+IF(ISNUMBER(T9),--(T9=1),0)) | AJ9: =IF(COUNT(AA9,Z9,AB9,AC9)=0,"",IF(ISNUMBER(AA9),--(AA9>=1.1),0)+IF(AND(ISNUMBER(Z9),ISNUMBER(I9)),--(Z9>=0.95*(220-I9)),0)+IF(ISNUMBER(AB9),--(AB9>=17),0)+IF(ISNUMBER(AC9),--(AC9=1),0)) | AK9: =IF(A9="","",TRIM(IF(COUNTIF($A$4:$A$33,A9)>1,"ID 중복 ","")&IF(LEN(A9)<>LEN(TRIM(A9)),"ID 앞뒤 공백 ","")&IF(AND(B9<>1,B9<>2),"집단코드 확인 ","")&IF(OR(D9="",AND(D9<>0,D9<>1)),"분석포함 코드 확인(빈칸=제외됨) ","")&IF(AND(ISNUMBER(D9),D9=0,E9=""),"제외 사유 없음 ","")&IF(AND(O9<>"",NOT(ISNUMBER(O9))),"사전VO2 숫자 아님 ","")&IF(AND(X9<>"",NOT(ISNUMBER(X9))),"사후VO2 숫자 아님 ","")&IF(AND(N9<>"",NOT(ISNUMBER(N9))),"사전체중 숫자 아님 ","")&IF(AND(W9<>"",NOT(ISNUMBER(W9))),"사후체중 숫자 아님 ","")&IF(ISNUMBER(O9),IF(OR(O9<25,O9>85),"사전VO2 범위(25–85) 확인 ",""),"")&IF(ISNUMBER(X9),IF(OR(X9<25,X9>85),"사후VO2 범위(25–85) 확인 ",""),"")&IF(AND(ISNUMBER(O9),ISNUMBER(X9)),IF(ABS(X9-O9)>12,"VO2 변화량 12 초과 확인 ",""),"")&IF(AND(ISNUMBER(P9),ISNUMBER(N9),ISNUMBER(O9)),IF(N9<=0,"사전 체중 확인 ",IF(ABS(P9/N9-O9)>0.5,"사전 절대값/체중≠상대값 ","")),"")&IF(AND(ISNUMBER(Y9),ISNUMBER(W9),ISNUMBER(X9)),IF(W9<=0,"사후 체중 확인 ",IF(ABS(Y9/W9-X9)>0.5,"사후 절대값/체중≠상대값 ","")),"")&IF(ISNUMBER(R9),IF(OR(R9<0.85,R9>1.5),"사전 RER 범위 확인 ",""),"")&IF(ISNUMBER(AA9),IF(OR(AA9<0.85,AA9>1.5),"사후 RER 범위 확인 ",""),"")&IF(ISNUMBER(Q9),IF(OR(Q9<150,Q9>225),"사전 최고심박 범위 확인 ",""),"")&IF(ISNUMBER(Z9),IF(OR(Z9<150,Z9>225),"사후 최고심박 범위 확인 ",""),"")&IF(AND(ISNUMBER(U9),ISNUMBER(AI9)),IF(AND(U9=1,AI9<2),"사전 판정충족=1이나 기준 2개 미만 ",""),"")&IF(AND(ISNUMBER(AD9),ISNUMBER(AJ9)),IF(AND(AD9=1,AJ9<2),"사후 판정충족=1이나 기준 2개 미만 ",""),"")&IF(AND(V9<>"",NOT(ISNUMBER(V9))),"사전 검사일 날짜형식 아님 ","")&IF(AND(AE9<>"",NOT(ISNUMBER(AE9))),"사후 검사일 날짜형식 아님 ","")&IF(AND(ISNUMBER(V9),ISNUMBER(AE9)),IF(AE9<=V9,"검사일 역전 ",IF(OR(AE9-V9<77,AE9-V9>126),"사전–사후 간격(11–18주) 확인 ","")),"")&IF(D9=1,IF(OR(NOT(ISNUMBER(O9)),NOT(ISNUMBER(X9))),"분석포함인데 VO2 결측 ",""),"")))
C10: =IF(B10="","",IF(B10=1,"실험군",IF(B10=2,"통제군","코드오류"))) | AF10: =IF(AND(ISNUMBER(O10),ISNUMBER(X10)),X10-O10,"") | AG10: =IF(AND(ISNUMBER(O10),ISNUMBER(X10)),IF(O10<>0,(X10-O10)/O10,""),"") | AH10: =IF(AND(ISNUMBER(N10),ISNUMBER(W10)),W10-N10,"") | AI10: =IF(COUNT(R10,Q10,S10,T10)=0,"",IF(ISNUMBER(R10),--(R10>=1.1),0)+IF(AND(ISNUMBER(Q10),ISNUMBER(I10)),--(Q10>=0.95*(220-I10)),0)+IF(ISNUMBER(S10),--(S10>=17),0)+IF(ISNUMBER(T10),--(T10=1),0)) | AJ10: =IF(COUNT(AA10,Z10,AB10,AC10)=0,"",IF(ISNUMBER(AA10),--(AA10>=1.1),0)+IF(AND(ISNUMBER(Z10),ISNUMBER(I10)),--(Z10>=0.95*(220-I10)),0)+IF(ISNUMBER(AB10),--(AB10>=17),0)+IF(ISNUMBER(AC10),--(AC10=1),0)) | AK10: =IF(A10="","",TRIM(IF(COUNTIF($A$4:$A$33,A10)>1,"ID 중복 ","")&IF(LEN(A10)<>LEN(TRIM(A10)),"ID 앞뒤 공백 ","")&IF(AND(B10<>1,B10<>2),"집단코드 확인 ","")&IF(OR(D10="",AND(D10<>0,D10<>1)),"분석포함 코드 확인(빈칸=제외됨) ","")&IF(AND(ISNUMBER(D10),D10=0,E10=""),"제외 사유 없음 ","")&IF(AND(O10<>"",NOT(ISNUMBER(O10))),"사전VO2 숫자 아님 ","")&IF(AND(X10<>"",NOT(ISNUMBER(X10))),"사후VO2 숫자 아님 ","")&IF(AND(N10<>"",NOT(ISNUMBER(N10))),"사전체중 숫자 아님 ","")&IF(AND(W10<>"",NOT(ISNUMBER(W10))),"사후체중 숫자 아님 ","")&IF(ISNUMBER(O10),IF(OR(O10<25,O10>85),"사전VO2 범위(25–85) 확인 ",""),"")&IF(ISNUMBER(X10),IF(OR(X10<25,X10>85),"사후VO2 범위(25–85) 확인 ",""),"")&IF(AND(ISNUMBER(O10),ISNUMBER(X10)),IF(ABS(X10-O10)>12,"VO2 변화량 12 초과 확인 ",""),"")&IF(AND(ISNUMBER(P10),ISNUMBER(N10),ISNUMBER(O10)),IF(N10<=0,"사전 체중 확인 ",IF(ABS(P10/N10-O10)>0.5,"사전 절대값/체중≠상대값 ","")),"")&IF(AND(ISNUMBER(Y10),ISNUMBER(W10),ISNUMBER(X10)),IF(W10<=0,"사후 체중 확인 ",IF(ABS(Y10/W10-X10)>0.5,"사후 절대값/체중≠상대값 ","")),"")&IF(ISNUMBER(R10),IF(OR(R10<0.85,R10>1.5),"사전 RER 범위 확인 ",""),"")&IF(ISNUMBER(AA10),IF(OR(AA10<0.85,AA10>1.5),"사후 RER 범위 확인 ",""),"")&IF(ISNUMBER(Q10),IF(OR(Q10<150,Q10>225),"사전 최고심박 범위 확인 ",""),"")&IF(ISNUMBER(Z10),IF(OR(Z10<150,Z10>225),"사후 최고심박 범위 확인 ",""),"")&IF(AND(ISNUMBER(U10),ISNUMBER(AI10)),IF(AND(U10=1,AI10<2),"사전 판정충족=1이나 기준 2개 미만 ",""),"")&IF(AND(ISNUMBER(AD10),ISNUMBER(AJ10)),IF(AND(AD10=1,AJ10<2),"사후 판정충족=1이나 기준 2개 미만 ",""),"")&IF(AND(V10<>"",NOT(ISNUMBER(V10))),"사전 검사일 날짜형식 아님 ","")&IF(AND(AE10<>"",NOT(ISNUMBER(AE10))),"사후 검사일 날짜형식 아님 ","")&IF(AND(ISNUMBER(V10),ISNUMBER(AE10)),IF(AE10<=V10,"검사일 역전 ",IF(OR(AE10-V10<77,AE10-V10>126),"사전–사후 간격(11–18주) 확인 ","")),"")&IF(D10=1,IF(OR(NOT(ISNUMBER(O10)),NOT(ISNUMBER(X10))),"분석포함인데 VO2 결측 ",""),"")))
C11: =IF(B11="","",IF(B11=1,"실험군",IF(B11=2,"통제군","코드오류"))) | AF11: =IF(AND(ISNUMBER(O11),ISNUMBER(X11)),X11-O11,"") | AG11: =IF(AND(ISNUMBER(O11),ISNUMBER(X11)),IF(O11<>0,(X11-O11)/O11,""),"") | AH11: =IF(AND(ISNUMBER(N11),ISNUMBER(W11)),W11-N11,"") | AI11: =IF(COUNT(R11,Q11,S11,T11)=0,"",IF(ISNUMBER(R11),--(R11>=1.1),0)+IF(AND(ISNUMBER(Q11),ISNUMBER(I11)),--(Q11>=0.95*(220-I11)),0)+IF(ISNUMBER(S11),--(S11>=17),0)+IF(ISNUMBER(T11),--(T11=1),0)) | AJ11: =IF(COUNT(AA11,Z11,AB11,AC11)=0,"",IF(ISNUMBER(AA11),--(AA11>=1.1),0)+IF(AND(ISNUMBER(Z11),ISNUMBER(I11)),--(Z11>=0.95*(220-I11)),0)+IF(ISNUMBER(AB11),--(AB11>=17),0)+IF(ISNUMBER(AC11),--(AC11=1),0)) | AK11: =IF(A11="","",TRIM(IF(COUNTIF($A$4:$A$33,A11)>1,"ID 중복 ","")&IF(LEN(A11)<>LEN(TRIM(A11)),"ID 앞뒤 공백 ","")&IF(AND(B11<>1,B11<>2),"집단코드 확인 ","")&IF(OR(D11="",AND(D11<>0,D11<>1)),"분석포함 코드 확인(빈칸=제외됨) ","")&IF(AND(ISNUMBER(D11),D11=0,E11=""),"제외 사유 없음 ","")&IF(AND(O11<>"",NOT(ISNUMBER(O11))),"사전VO2 숫자 아님 ","")&IF(AND(X11<>"",NOT(ISNUMBER(X11))),"사후VO2 숫자 아님 ","")&IF(AND(N11<>"",NOT(ISNUMBER(N11))),"사전체중 숫자 아님 ","")&IF(AND(W11<>"",NOT(ISNUMBER(W11))),"사후체중 숫자 아님 ","")&IF(ISNUMBER(O11),IF(OR(O11<25,O11>85),"사전VO2 범위(25–85) 확인 ",""),"")&IF(ISNUMBER(X11),IF(OR(X11<25,X11>85),"사후VO2 범위(25–85) 확인 ",""),"")&IF(AND(ISNUMBER(O11),ISNUMBER(X11)),IF(ABS(X11-O11)>12,"VO2 변화량 12 초과 확인 ",""),"")&IF(AND(ISNUMBER(P11),ISNUMBER(N11),ISNUMBER(O11)),IF(N11<=0,"사전 체중 확인 ",IF(ABS(P11/N11-O11)>0.5,"사전 절대값/체중≠상대값 ","")),"")&IF(AND(ISNUMBER(Y11),ISNUMBER(W11),ISNUMBER(X11)),IF(W11<=0,"사후 체중 확인 ",IF(ABS(Y11/W11-X11)>0.5,"사후 절대값/체중≠상대값 ","")),"")&IF(ISNUMBER(R11),IF(OR(R11<0.85,R11>1.5),"사전 RER 범위 확인 ",""),"")&IF(ISNUMBER(AA11),IF(OR(AA11<0.85,AA11>1.5),"사후 RER 범위 확인 ",""),"")&IF(ISNUMBER(Q11),IF(OR(Q11<150,Q11>225),"사전 최고심박 범위 확인 ",""),"")&IF(ISNUMBER(Z11),IF(OR(Z11<150,Z11>225),"사후 최고심박 범위 확인 ",""),"")&IF(AND(ISNUMBER(U11),ISNUMBER(AI11)),IF(AND(U11=1,AI11<2),"사전 판정충족=1이나 기준 2개 미만 ",""),"")&IF(AND(ISNUMBER(AD11),ISNUMBER(AJ11)),IF(AND(AD11=1,AJ11<2),"사후 판정충족=1이나 기준 2개 미만 ",""),"")&IF(AND(V11<>"",NOT(ISNUMBER(V11))),"사전 검사일 날짜형식 아님 ","")&IF(AND(AE11<>"",NOT(ISNUMBER(AE11))),"사후 검사일 날짜형식 아님 ","")&IF(AND(ISNUMBER(V11),ISNUMBER(AE11)),IF(AE11<=V11,"검사일 역전 ",IF(OR(AE11-V11<77,AE11-V11>126),"사전–사후 간격(11–18주) 확인 ","")),"")&IF(D11=1,IF(OR(NOT(ISNUMBER(O11)),NOT(ISNUMBER(X11))),"분석포함인데 VO2 결측 ",""),"")))
C12: =IF(B12="","",IF(B12=1,"실험군",IF(B12=2,"통제군","코드오류"))) | AF12: =IF(AND(ISNUMBER(O12),ISNUMBER(X12)),X12-O12,"") | AG12: =IF(AND(ISNUMBER(O12),ISNUMBER(X12)),IF(O12<>0,(X12-O12)/O12,""),"") | AH12: =IF(AND(ISNUMBER(N12),ISNUMBER(W12)),W12-N12,"") | AI12: =IF(COUNT(R12,Q12,S12,T12)=0,"",IF(ISNUMBER(R12),--(R12>=1.1),0)+IF(AND(ISNUMBER(Q12),ISNUMBER(I12)),--(Q12>=0.95*(220-I12)),0)+IF(ISNUMBER(S12),--(S12>=17),0)+IF(ISNUMBER(T12),--(T12=1),0)) | AJ12: =IF(COUNT(AA12,Z12,AB12,AC12)=0,"",IF(ISNUMBER(AA12),--(AA12>=1.1),0)+IF(AND(ISNUMBER(Z12),ISNUMBER(I12)),--(Z12>=0.95*(220-I12)),0)+IF(ISNUMBER(AB12),--(AB12>=17),0)+IF(ISNUMBER(AC12),--(AC12=1),0)) | AK12: =IF(A12="","",TRIM(IF(COUNTIF($A$4:$A$33,A12)>1,"ID 중복 ","")&IF(LEN(A12)<>LEN(TRIM(A12)),"ID 앞뒤 공백 ","")&IF(AND(B12<>1,B12<>2),"집단코드 확인 ","")&IF(OR(D12="",AND(D12<>0,D12<>1)),"분석포함 코드 확인(빈칸=제외됨) ","")&IF(AND(ISNUMBER(D12),D12=0,E12=""),"제외 사유 없음 ","")&IF(AND(O12<>"",NOT(ISNUMBER(O12))),"사전VO2 숫자 아님 ","")&IF(AND(X12<>"",NOT(ISNUMBER(X12))),"사후VO2 숫자 아님 ","")&IF(AND(N12<>"",NOT(ISNUMBER(N12))),"사전체중 숫자 아님 ","")&IF(AND(W12<>"",NOT(ISNUMBER(W12))),"사후체중 숫자 아님 ","")&IF(ISNUMBER(O12),IF(OR(O12<25,O12>85),"사전VO2 범위(25–85) 확인 ",""),"")&IF(ISNUMBER(X12),IF(OR(X12<25,X12>85),"사후VO2 범위(25–85) 확인 ",""),"")&IF(AND(ISNUMBER(O12),ISNUMBER(X12)),IF(ABS(X12-O12)>12,"VO2 변화량 12 초과 확인 ",""),"")&IF(AND(ISNUMBER(P12),ISNUMBER(N12),ISNUMBER(O12)),IF(N12<=0,"사전 체중 확인 ",IF(ABS(P12/N12-O12)>0.5,"사전 절대값/체중≠상대값 ","")),"")&IF(AND(ISNUMBER(Y12),ISNUMBER(W12),ISNUMBER(X12)),IF(W12<=0,"사후 체중 확인 ",IF(ABS(Y12/W12-X12)>0.5,"사후 절대값/체중≠상대값 ","")),"")&IF(ISNUMBER(R12),IF(OR(R12<0.85,R12>1.5),"사전 RER 범위 확인 ",""),"")&IF(ISNUMBER(AA12),IF(OR(AA12<0.85,AA12>1.5),"사후 RER 범위 확인 ",""),"")&IF(ISNUMBER(Q12),IF(OR(Q12<150,Q12>225),"사전 최고심박 범위 확인 ",""),"")&IF(ISNUMBER(Z12),IF(OR(Z12<150,Z12>225),"사후 최고심박 범위 확인 ",""),"")&IF(AND(ISNUMBER(U12),ISNUMBER(AI12)),IF(AND(U12=1,AI12<2),"사전 판정충족=1이나 기준 2개 미만 ",""),"")&IF(AND(ISNUMBER(AD12),ISNUMBER(AJ12)),IF(AND(AD12=1,AJ12<2),"사후 판정충족=1이나 기준 2개 미만 ",""),"")&IF(AND(V12<>"",NOT(ISNUMBER(V12))),"사전 검사일 날짜형식 아님 ","")&IF(AND(AE12<>"",NOT(ISNUMBER(AE12))),"사후 검사일 날짜형식 아님 ","")&IF(AND(ISNUMBER(V12),ISNUMBER(AE12)),IF(AE12<=V12,"검사일 역전 ",IF(OR(AE12-V12<77,AE12-V12>126),"사전–사후 간격(11–18주) 확인 ","")),"")&IF(D12=1,IF(OR(NOT(ISNUMBER(O12)),NOT(ISNUMBER(X12))),"분석포함인데 VO2 결측 ",""),"")))
C13: =IF(B13="","",IF(B13=1,"실험군",IF(B13=2,"통제군","코드오류"))) | AF13: =IF(AND(ISNUMBER(O13),ISNUMBER(X13)),X13-O13,"") | AG13: =IF(AND(ISNUMBER(O13),ISNUMBER(X13)),IF(O13<>0,(X13-O13)/O13,""),"") | AH13: =IF(AND(ISNUMBER(N13),ISNUMBER(W13)),W13-N13,"") | AI13: =IF(COUNT(R13,Q13,S13,T13)=0,"",IF(ISNUMBER(R13),--(R13>=1.1),0)+IF(AND(ISNUMBER(Q13),ISNUMBER(I13)),--(Q13>=0.95*(220-I13)),0)+IF(ISNUMBER(S13),--(S13>=17),0)+IF(ISNUMBER(T13),--(T13=1),0)) | AJ13: =IF(COUNT(AA13,Z13,AB13,AC13)=0,"",IF(ISNUMBER(AA13),--(AA13>=1.1),0)+IF(AND(ISNUMBER(Z13),ISNUMBER(I13)),--(Z13>=0.95*(220-I13)),0)+IF(ISNUMBER(AB13),--(AB13>=17),0)+IF(ISNUMBER(AC13),--(AC13=1),0)) | AK13: =IF(A13="","",TRIM(IF(COUNTIF($A$4:$A$33,A13)>1,"ID 중복 ","")&IF(LEN(A13)<>LEN(TRIM(A13)),"ID 앞뒤 공백 ","")&IF(AND(B13<>1,B13<>2),"집단코드 확인 ","")&IF(OR(D13="",AND(D13<>0,D13<>1)),"분석포함 코드 확인(빈칸=제외됨) ","")&IF(AND(ISNUMBER(D13),D13=0,E13=""),"제외 사유 없음 ","")&IF(AND(O13<>"",NOT(ISNUMBER(O13))),"사전VO2 숫자 아님 ","")&IF(AND(X13<>"",NOT(ISNUMBER(X13))),"사후VO2 숫자 아님 ","")&IF(AND(N13<>"",NOT(ISNUMBER(N13))),"사전체중 숫자 아님 ","")&IF(AND(W13<>"",NOT(ISNUMBER(W13))),"사후체중 숫자 아님 ","")&IF(ISNUMBER(O13),IF(OR(O13<25,O13>85),"사전VO2 범위(25–85) 확인 ",""),"")&IF(ISNUMBER(X13),IF(OR(X13<25,X13>85),"사후VO2 범위(25–85) 확인 ",""),"")&IF(AND(ISNUMBER(O13),ISNUMBER(X13)),IF(ABS(X13-O13)>12,"VO2 변화량 12 초과 확인 ",""),"")&IF(AND(ISNUMBER(P13),ISNUMBER(N13),ISNUMBER(O13)),IF(N13<=0,"사전 체중 확인 ",IF(ABS(P13/N13-O13)>0.5,"사전 절대값/체중≠상대값 ","")),"")&IF(AND(ISNUMBER(Y13),ISNUMBER(W13),ISNUMBER(X13)),IF(W13<=0,"사후 체중 확인 ",IF(ABS(Y13/W13-X13)>0.5,"사후 절대값/체중≠상대값 ","")),"")&IF(ISNUMBER(R13),IF(OR(R13<0.85,R13>1.5),"사전 RER 범위 확인 ",""),"")&IF(ISNUMBER(AA13),IF(OR(AA13<0.85,AA13>1.5),"사후 RER 범위 확인 ",""),"")&IF(ISNUMBER(Q13),IF(OR(Q13<150,Q13>225),"사전 최고심박 범위 확인 ",""),"")&IF(ISNUMBER(Z13),IF(OR(Z13<150,Z13>225),"사후 최고심박 범위 확인 ",""),"")&IF(AND(ISNUMBER(U13),ISNUMBER(AI13)),IF(AND(U13=1,AI13<2),"사전 판정충족=1이나 기준 2개 미만 ",""),"")&IF(AND(ISNUMBER(AD13),ISNUMBER(AJ13)),IF(AND(AD13=1,AJ13<2),"사후 판정충족=1이나 기준 2개 미만 ",""),"")&IF(AND(V13<>"",NOT(ISNUMBER(V13))),"사전 검사일 날짜형식 아님 ","")&IF(AND(AE13<>"",NOT(ISNUMBER(AE13))),"사후 검사일 날짜형식 아님 ","")&IF(AND(ISNUMBER(V13),ISNUMBER(AE13)),IF(AE13<=V13,"검사일 역전 ",IF(OR(AE13-V13<77,AE13-V13>126),"사전–사후 간격(11–18주) 확인 ","")),"")&IF(D13=1,IF(OR(NOT(ISNUMBER(O13)),NOT(ISNUMBER(X13))),"분석포함인데 VO2 결측 ",""),"")))
C14: =IF(B14="","",IF(B14=1,"실험군",IF(B14=2,"통제군","코드오류"))) | AF14: =IF(AND(ISNUMBER(O14),ISNUMBER(X14)),X14-O14,"") | AG14: =IF(AND(ISNUMBER(O14),ISNUMBER(X14)),IF(O14<>0,(X14-O14)/O14,""),"") | AH14: =IF(AND(ISNUMBER(N14),ISNUMBER(W14)),W14-N14,"") | AI14: =IF(COUNT(R14,Q14,S14,T14)=0,"",IF(ISNUMBER(R14),--(R14>=1.1),0)+IF(AND(ISNUMBER(Q14),ISNUMBER(I14)),--(Q14>=0.95*(220-I14)),0)+IF(ISNUMBER(S14),--(S14>=17),0)+IF(ISNUMBER(T14),--(T14=1),0)) | AJ14: =IF(COUNT(AA14,Z14,AB14,AC14)=0,"",IF(ISNUMBER(AA14),--(AA14>=1.1),0)+IF(AND(ISNUMBER(Z14),ISNUMBER(I14)),--(Z14>=0.95*(220-I14)),0)+IF(ISNUMBER(AB14),--(AB14>=17),0)+IF(ISNUMBER(AC14),--(AC14=1),0)) | AK14: =IF(A14="","",TRIM(IF(COUNTIF($A$4:$A$33,A14)>1,"ID 중복 ","")&IF(LEN(A14)<>LEN(TRIM(A14)),"ID 앞뒤 공백 ","")&IF(AND(B14<>1,B14<>2),"집단코드 확인 ","")&IF(OR(D14="",AND(D14<>0,D14<>1)),"분석포함 코드 확인(빈칸=제외됨) ","")&IF(AND(ISNUMBER(D14),D14=0,E14=""),"제외 사유 없음 ","")&IF(AND(O14<>"",NOT(ISNUMBER(O14))),"사전VO2 숫자 아님 ","")&IF(AND(X14<>"",NOT(ISNUMBER(X14))),"사후VO2 숫자 아님 ","")&IF(AND(N14<>"",NOT(ISNUMBER(N14))),"사전체중 숫자 아님 ","")&IF(AND(W14<>"",NOT(ISNUMBER(W14))),"사후체중 숫자 아님 ","")&IF(ISNUMBER(O14),IF(OR(O14<25,O14>85),"사전VO2 범위(25–85) 확인 ",""),"")&IF(ISNUMBER(X14),IF(OR(X14<25,X14>85),"사후VO2 범위(25–85) 확인 ",""),"")&IF(AND(ISNUMBER(O14),ISNUMBER(X14)),IF(ABS(X14-O14)>12,"VO2 변화량 12 초과 확인 ",""),"")&IF(AND(ISNUMBER(P14),ISNUMBER(N14),ISNUMBER(O14)),IF(N14<=0,"사전 체중 확인 ",IF(ABS(P14/N14-O14)>0.5,"사전 절대값/체중≠상대값 ","")),"")&IF(AND(ISNUMBER(Y14),ISNUMBER(W14),ISNUMBER(X14)),IF(W14<=0,"사후 체중 확인 ",IF(ABS(Y14/W14-X14)>0.5,"사후 절대값/체중≠상대값 ","")),"")&IF(ISNUMBER(R14),IF(OR(R14<0.85,R14>1.5),"사전 RER 범위 확인 ",""),"")&IF(ISNUMBER(AA14),IF(OR(AA14<0.85,AA14>1.5),"사후 RER 범위 확인 ",""),"")&IF(ISNUMBER(Q14),IF(OR(Q14<150,Q14>225),"사전 최고심박 범위 확인 ",""),"")&IF(ISNUMBER(Z14),IF(OR(Z14<150,Z14>225),"사후 최고심박 범위 확인 ",""),"")&IF(AND(ISNUMBER(U14),ISNUMBER(AI14)),IF(AND(U14=1,AI14<2),"사전 판정충족=1이나 기준 2개 미만 ",""),"")&IF(AND(ISNUMBER(AD14),ISNUMBER(AJ14)),IF(AND(AD14=1,AJ14<2),"사후 판정충족=1이나 기준 2개 미만 ",""),"")&IF(AND(V14<>"",NOT(ISNUMBER(V14))),"사전 검사일 날짜형식 아님 ","")&IF(AND(AE14<>"",NOT(ISNUMBER(AE14))),"사후 검사일 날짜형식 아님 ","")&IF(AND(ISNUMBER(V14),ISNUMBER(AE14)),IF(AE14<=V14,"검사일 역전 ",IF(OR(AE14-V14<77,AE14-V14>126),"사전–사후 간격(11–18주) 확인 ","")),"")&IF(D14=1,IF(OR(NOT(ISNUMBER(O14)),NOT(ISNUMBER(X14))),"분석포함인데 VO2 결측 ",""),"")))
C15: =IF(B15="","",IF(B15=1,"실험군",IF(B15=2,"통제군","코드오류"))) | AF15: =IF(AND(ISNUMBER(O15),ISNUMBER(X15)),X15-O15,"") | AG15: =IF(AND(ISNUMBER(O15),ISNUMBER(X15)),IF(O15<>0,(X15-O15)/O15,""),"") | AH15: =IF(AND(ISNUMBER(N15),ISNUMBER(W15)),W15-N15,"") | AI15: =IF(COUNT(R15,Q15,S15,T15)=0,"",IF(ISNUMBER(R15),--(R15>=1.1),0)+IF(AND(ISNUMBER(Q15),ISNUMBER(I15)),--(Q15>=0.95*(220-I15)),0)+IF(ISNUMBER(S15),--(S15>=17),0)+IF(ISNUMBER(T15),--(T15=1),0)) | AJ15: =IF(COUNT(AA15,Z15,AB15,AC15)=0,"",IF(ISNUMBER(AA15),--(AA15>=1.1),0)+IF(AND(ISNUMBER(Z15),ISNUMBER(I15)),--(Z15>=0.95*(220-I15)),0)+IF(ISNUMBER(AB15),--(AB15>=17),0)+IF(ISNUMBER(AC15),--(AC15=1),0)) | AK15: =IF(A15="","",TRIM(IF(COUNTIF($A$4:$A$33,A15)>1,"ID 중복 ","")&IF(LEN(A15)<>LEN(TRIM(A15)),"ID 앞뒤 공백 ","")&IF(AND(B15<>1,B15<>2),"집단코드 확인 ","")&IF(OR(D15="",AND(D15<>0,D15<>1)),"분석포함 코드 확인(빈칸=제외됨) ","")&IF(AND(ISNUMBER(D15),D15=0,E15=""),"제외 사유 없음 ","")&IF(AND(O15<>"",NOT(ISNUMBER(O15))),"사전VO2 숫자 아님 ","")&IF(AND(X15<>"",NOT(ISNUMBER(X15))),"사후VO2 숫자 아님 ","")&IF(AND(N15<>"",NOT(ISNUMBER(N15))),"사전체중 숫자 아님 ","")&IF(AND(W15<>"",NOT(ISNUMBER(W15))),"사후체중 숫자 아님 ","")&IF(ISNUMBER(O15),IF(OR(O15<25,O15>85),"사전VO2 범위(25–85) 확인 ",""),"")&IF(ISNUMBER(X15),IF(OR(X15<25,X15>85),"사후VO2 범위(25–85) 확인 ",""),"")&IF(AND(ISNUMBER(O15),ISNUMBER(X15)),IF(ABS(X15-O15)>12,"VO2 변화량 12 초과 확인 ",""),"")&IF(AND(ISNUMBER(P15),ISNUMBER(N15),ISNUMBER(O15)),IF(N15<=0,"사전 체중 확인 ",IF(ABS(P15/N15-O15)>0.5,"사전 절대값/체중≠상대값 ","")),"")&IF(AND(ISNUMBER(Y15),ISNUMBER(W15),ISNUMBER(X15)),IF(W15<=0,"사후 체중 확인 ",IF(ABS(Y15/W15-X15)>0.5,"사후 절대값/체중≠상대값 ","")),"")&IF(ISNUMBER(R15),IF(OR(R15<0.85,R15>1.5),"사전 RER 범위 확인 ",""),"")&IF(ISNUMBER(AA15),IF(OR(AA15<0.85,AA15>1.5),"사후 RER 범위 확인 ",""),"")&IF(ISNUMBER(Q15),IF(OR(Q15<150,Q15>225),"사전 최고심박 범위 확인 ",""),"")&IF(ISNUMBER(Z15),IF(OR(Z15<150,Z15>225),"사후 최고심박 범위 확인 ",""),"")&IF(AND(ISNUMBER(U15),ISNUMBER(AI15)),IF(AND(U15=1,AI15<2),"사전 판정충족=1이나 기준 2개 미만 ",""),"")&IF(AND(ISNUMBER(AD15),ISNUMBER(AJ15)),IF(AND(AD15=1,AJ15<2),"사후 판정충족=1이나 기준 2개 미만 ",""),"")&IF(AND(V15<>"",NOT(ISNUMBER(V15))),"사전 검사일 날짜형식 아님 ","")&IF(AND(AE15<>"",NOT(ISNUMBER(AE15))),"사후 검사일 날짜형식 아님 ","")&IF(AND(ISNUMBER(V15),ISNUMBER(AE15)),IF(AE15<=V15,"검사일 역전 ",IF(OR(AE15-V15<77,AE15-V15>126),"사전–사후 간격(11–18주) 확인 ","")),"")&IF(D15=1,IF(OR(NOT(ISNUMBER(O15)),NOT(ISNUMBER(X15))),"분석포함인데 VO2 결측 ",""),"")))
... C33: =IF(B33="","",IF(B33=1,"실험군",IF(B33=2,"통제군","코드오류"))) | AF33: =IF(AND(ISNUMBER(O33),ISNUMBER(X33)),X33-O33,"") | AG33: =IF(AND(ISNUMBER(O33),ISNUMBER(X33)),IF(O33<>0,(X33-O33)/O33,""),"") | AH33: =IF(AND(ISNUMBER(N33),ISNUMBER(W33)),W33-N33,"") | AI33: =IF(COUNT(R33,Q33,S33,T33)=0,"",IF(ISNUMBER(R33),--(R33>=1.1),0)+IF(AND(ISNUMBER(Q33),ISNUMBER(I33)),--(Q33>=0.95*(220-I33)),0)+IF(ISNUMBER(S33),--(S33>=17),0)+IF(ISNUMBER(T33),--(T33=1),0)) | AJ33: =IF(COUNT(AA33,Z33,AB33,AC33)=0,"",IF(ISNUMBER(AA33),--(AA33>=1.1),0)+IF(AND(ISNUMBER(Z33),ISNUMBER(I33)),--(Z33>=0.95*(220-I33)),0)+IF(ISNUMBER(AB33),--(AB33>=17),0)+IF(ISNUMBER(AC33),--(AC33=1),0)) | AK33: =IF(A33="","",TRIM(IF(COUNTIF($A$4:$A$33,A33)>1,"ID 중복 ","")&IF(LEN(A33)<>LEN(TRIM(A33)),"ID 앞뒤 공백 ","")&IF(AND(B33<>1,B33<>2),"집단코드 확인 ","")&IF(OR(D33="",AND(D33<>0,D33<>1)),"분석포함 코드 확인(빈칸=제외됨) ","")&IF(AND(ISNUMBER(D33),D33=0,E33=""),"제외 사유 없음 ","")&IF(AND(O33<>"",NOT(ISNUMBER(O33))),"사전VO2 숫자 아님 ","")&IF(AND(X33<>"",NOT(ISNUMBER(X33))),"사후VO2 숫자 아님 ","")&IF(AND(N33<>"",NOT(ISNUMBER(N33))),"사전체중 숫자 아님 ","")&IF(AND(W33<>"",NOT(ISNUMBER(W33))),"사후체중 숫자 아님 ","")&IF(ISNUMBER(O33),IF(OR(O33<25,O33>85),"사전VO2 범위(25–85) 확인 ",""),"")&IF(ISNUMBER(X33),IF(OR(X33<25,X33>85),"사후VO2 범위(25–85) 확인 ",""),"")&IF(AND(ISNUMBER(O33),ISNUMBER(X33)),IF(ABS(X33-O33)>12,"VO2 변화량 12 초과 확인 ",""),"")&IF(AND(ISNUMBER(P33),ISNUMBER(N33),ISNUMBER(O33)),IF(N33<=0,"사전 체중 확인 ",IF(ABS(P33/N33-O33)>0.5,"사전 절대값/체중≠상대값 ","")),"")&IF(AND(ISNUMBER(Y33),ISNUMBER(W33),ISNUMBER(X33)),IF(W33<=0,"사후 체중 확인 ",IF(ABS(Y33/W33-X33)>0.5,"사후 절대값/체중≠상대값 ","")),"")&IF(ISNUMBER(R33),IF(OR(R33<0.85,R33>1.5),"사전 RER 범위 확인 ",""),"")&IF(ISNUMBER(AA33),IF(OR(AA33<0.85,AA33>1.5),"사후 RER 범위 확인 ",""),"")&IF(ISNUMBER(Q33),IF(OR(Q33<150,Q33>225),"사전 최고심박 범위 확인 ",""),"")&IF(ISNUMBER(Z33),IF(OR(Z33<150,Z33>225),"사후 최고심박 범위 확인 ",""),"")&IF(AND(ISNUMBER(U33),ISNUMBER(AI33)),IF(AND(U33=1,AI33<2),"사전 판정충족=1이나 기준 2개 미만 ",""),"")&IF(AND(ISNUMBER(AD33),ISNUMBER(AJ33)),IF(AND(AD33=1,AJ33<2),"사후 판정충족=1이나 기준 2개 미만 ",""),"")&IF(AND(V33<>"",NOT(ISNUMBER(V33))),"사전 검사일 날짜형식 아님 ","")&IF(AND(AE33<>"",NOT(ISNUMBER(AE33))),"사후 검사일 날짜형식 아님 ","")&IF(AND(ISNUMBER(V33),ISNUMBER(AE33)),IF(AE33<=V33,"검사일 역전 ",IF(OR(AE33-V33<77,AE33-V33>126),"사전–사후 간격(11–18주) 확인 ","")),"")&IF(D33=1,IF(OR(NOT(ISNUMBER(O33)),NOT(ISNUMBER(X33))),"분석포함인데 VO2 결측 ",""),"")))

Sheet FMS
A1: ID | B1: group | C1: include | D1: include_fms | E1: rater_pre | F1: date_fms_pre | G1: DS_pre | H1: HS_L_pre | I1: HS_R_pre | J1: ILL_L_pre | K1: ILL_R_pre | L1: SM_L_pre | M1: SM_R_pre | N1: SM_clr_pre | O1: ASLR_L_pre | P1: ASLR_R_pre | Q1: TSPU_pre | R1: TSPU_clr_pre | S1: RS_L_pre | T1: RS_R_pre | U1: RS_clr_pre | V1: fms_spss_pre | W1: rater_post | X1: date_fms_post | Y1: DS_post | Z1: HS_L_post | AA1: HS_R_post | AB1: ILL_L_post | AC1: ILL_R_post | AD1: SM_L_post | AE1: SM_R_post | AF1: SM_clr_post | AG1: ASLR_L_post | AH1: ASLR_R_post | AI1: TSPU_post | AJ1: TSPU_clr_post | AK1: RS_L_post | AL1: RS_R_post | AM1: RS_clr_post | AN1: fms_spss_post | AO1: DSs_pre | AP1: HSs_pre | AQ1: ILLs_pre | AR1: SMs_pre | AS1: ASLRs_pre | AT1: TSPUs_pre | AU1: RSs_pre | AV1: fms_calc_pre | AW1: asym_pre | AX1: clrn_pre | AY1: DSs_post | AZ1: HSs_post | BA1: ILLs_post | BB1: SMs_post | BC1: ASLRs_post | BD1: TSPUs_post | BE1: RSs_post | BF1: fms_calc_post | BG1: asym_post | BH1: clrn_post | BI1: fms_pre | BJ1: fms_post | BK1: d_fms | BL1: src_pre | BM1: src_post | BN1: r2_pre | BO1: r2_post | BP1: avg_pre | BQ1: avg_post | BR1: d_avg | BS1: chk_fms
A2: 대상자 ID (직접 입력) | B2: 집단 (자동) | C2: 분석 포함 (자동) | D2: FMS만 분석포함 1/0 (비우면 대상자 시트 따름) | E2: 사전 평가자 (코드) | F2: 사전 FMS 검사일 | G2: 사전 DS (0–3) | H2: 사전 HS 좌 (0–3) | I2: 사전 HS 우 (0–3) | J2: 사전 ILL 좌 (0–3) | K2: 사전 ILL 우 (0–3) | L2: 사전 SM 좌 (0–3) | M2: 사전 SM 우 (0–3) | N2: 사전 SM clearing 통증 1/0 (좌·우 중 하나라도) | O2: 사전 ASLR 좌 (0–3) | P2: 사전 ASLR 우 (0–3) | Q2: 사전 TSPU (0–3) | R2: 사전 TSPU clearing 통증 1/0 | S2: 사전 RS 좌 (0–3) | T2: 사전 RS 우 (0–3) | U2: 사전 RS clearing 통증 1/0 | V2: 사전 총점 기존 SPSS· 포스터 값 (있으면) | W2: 사후 평가자 (코드) | X2: 사후 FMS 검사일 | Y2: 사후 DS (0–3) | Z2: 사후 HS 좌 (0–3) | AA2: 사후 HS 우 (0–3) | AB2: 사후 ILL 좌 (0–3) | AC2: 사후 ILL 우 (0–3) | AD2: 사후 SM 좌 (0–3) | AE2: 사후 SM 우 (0–3) | AF2: 사후 SM clearing 통증 1/0 (좌·우 중 하나라도) | AG2: 사후 ASLR 좌 (0–3) | AH2: 사후 ASLR 우 (0–3) | AI2: 사후 TSPU (0–3) | AJ2: 사후 TSPU clearing 통증 1/0 | AK2: 사후 RS 좌 (0–3) | AL2: 사후 RS 우 (0–3) | AM2: 사후 RS clearing 통증 1/0 | AN2: 사후 총점 기존 SPSS· 포스터 값 (있으면) | AO2: 사전 DS 점수 (자동) | AP2: 사전 HS 점수 (자동) | AQ2: 사전 ILL 점수 (자동) | AR2: 사전 SM 점수 (자동) | AS2: 사전 ASLR 점수 (자동) | AT2: 사전 TSPU 점수 (자동) | AU2: 사전 RS 점수 (자동) | AV2: 사전 하위항목 합 (자동) | AW2: 사전 좌우 비대칭 항목 수 (자동) | AX2: 사전 clearing 기록 수 (자동) | AY2: 사후 DS 점수 (자동) | AZ2: 사후 HS 점수 (자동) | BA2: 사후 ILL 점수 (자동) | BB2: 사후 SM 점수 (자동) | BC2: 사후 ASLR 점수 (자동) | BD2: 사후 TSPU 점수 (자동) | BE2: 사후 RS 점수 (자동) | BF2: 사후 하위항목 합 (자동) | BG2: 사후 좌우 비대칭 항목 수 (자동) | BH2: 사후 clearing 기록 수 (자동) | BI2: 분석용 사전 총점 (자동) | BJ2: 분석용 사후 총점 (자동) | BK2: FMS 변화 사후−사전 (자동) | BL2: 사전 총점 출처 (자동) | BM2: 사후 총점 출처 (자동) | BN2: 평가자2 사전 총점 (자동) | BO2: 평가자2 사후 총점 (자동) | BP2: 평가자 평균 사전 총점 (자동) | BQ2: 평가자 평균 사후 총점 (자동) | BR2: 평가자 평균 변화 (자동) | BS2: 자동 점검 (경고가 있으면 주황색)
A3: 예시 | B3: 1 | C3: 0 | E3: R1 | F3: 45720 | G3: 2 | H3: 2 | I3: 2 | J3: 2 | K3: 3 | L3: 3 | M3: 2 | N3: 0 | O3: 2 | P3: 2 | Q3: 2 | R3: 0 | S3: 2 | T3: 2 | U3: 0 | V3: 14 | W3: R1 | X3: 45808 | Y3: 3 | Z3: 2 | AA3: 3 | AB3: 3 | AC3: 3 | AD3: 3 | AE3: 2 | AF3: 0 | AG3: 3 | AH3: 2 | AI3: 2 | AJ3: 0 | AK3: 2 | AL3: 2 | AM3: 0 | AN3: 16 | AO3: =IF(ISNUMBER(G3),G3,"") | AP3: =IF(AND(ISNUMBER(H3),ISNUMBER(I3)),MIN(H3,I3),"") | AQ3: =IF(AND(ISNUMBER(J3),ISNUMBER(K3)),MIN(J3,K3),"") | AR3: =IF(AND(ISNUMBER(L3),ISNUMBER(M3)),IF(N3=1,0,MIN(L3,M3)),"") | AS3: =IF(AND(ISNUMBER(O3),ISNUMBER(P3)),MIN(O3,P3),"") | AT3: =IF(ISNUMBER(Q3),IF(R3=1,0,Q3),"") | AU3: =IF(AND(ISNUMBER(S3),ISNUMBER(T3)),IF(U3=1,0,MIN(S3,T3)),"") | AV3: =IF(COUNT(AO3:AU3)=7,SUM(AO3:AU3),"") | AW3: =IF(ISNUMBER(AV3),--(H3<>I3)+--(J3<>K3)+--(L3<>M3)+--(O3<>P3)+--(S3<>T3),"") | AX3: =IF(ISNUMBER(AV3),COUNT(N3,R3,U3),"") | AY3: =IF(ISNUMBER(Y3),Y3,"") | AZ3: =IF(AND(ISNUMBER(Z3),ISNUMBER(AA3)),MIN(Z3,AA3),"") | BA3: =IF(AND(ISNUMBER(AB3),ISNUMBER(AC3)),MIN(AB3,AC3),"") | BB3: =IF(AND(ISNUMBER(AD3),ISNUMBER(AE3)),IF(AF3=1,0,MIN(AD3,AE3)),"") | BC3: =IF(AND(ISNUMBER(AG3),ISNUMBER(AH3)),MIN(AG3,AH3),"") | BD3: =IF(ISNUMBER(AI3),IF(AJ3=1,0,AI3),"") | BE3: =IF(AND(ISNUMBER(AK3),ISNUMBER(AL3)),IF(AM3=1,0,MIN(AK3,AL3)),"") | BF3: =IF(COUNT(AY3:BE3)=7,SUM(AY3:BE3),"") | BG3: =IF(ISNUMBER(BF3),--(Z3<>AA3)+--(AB3<>AC3)+--(AD3<>AE3)+--(AG3<>AH3)+--(AK3<>AL3),"") | BH3: =IF(ISNUMBER(BF3),COUNT(AF3,AJ3,AM3),"") | BI3: =IF(ISNUMBER(AV3),AV3,IF(ISNUMBER(V3),V3,"")) | BJ3: =IF(ISNUMBER(BF3),BF3,IF(ISNUMBER(AN3),AN3,"")) | BK3: =IF(AND(ISNUMBER(BI3),ISNUMBER(BJ3)),BJ3-BI3,"") | BL3: =IF(ISNUMBER(AV3),"하위항목",IF(ISNUMBER(V3),"SPSS총점","")) | BM3: =IF(ISNUMBER(BF3),"하위항목",IF(ISNUMBER(AN3),"SPSS총점","")) | BN3: =IF($A3="","",IFERROR(IF(ISNUMBER(INDEX('FMS_평가자2'!$AP$4:$AP$33,MATCH($A3,'FMS_평가자2'!$A$4:$A$33,0))),INDEX('FMS_평가자2'!$AP$4:$AP$33,MATCH($A3,'FMS_평가자2'!$A$4:$A$33,0)),""),"")) | BO3: =IF($A3="","",IFERROR(IF(ISNUMBER(INDEX('FMS_평가자2'!$AY$4:$AY$33,MATCH($A3,'FMS_평가자2'!$A$4:$A$33,0))),INDEX('FMS_평가자2'!$AY$4:$AY$33,MATCH($A3,'FMS_평가자2'!$A$4:$A$33,0)),""),"")) | BP3: =IF(AND(ISNUMBER(AV3),ISNUMBER(BN3)),(AV3+BN3)/2,"") | BQ3: =IF(AND(ISNUMBER(BF3),ISNUMBER(BO3)),(BF3+BO3)/2,"") | BR3: =IF(AND(ISNUMBER(BP3),ISNUMBER(BQ3)),BQ3-BP3,"")
B4: =IF($A4="","",IFERROR(IF(INDEX('대상자_VO2max'!$B$4:$B$33,MATCH($A4,'대상자_VO2max'!$A$4:$A$33,0))="","",INDEX('대상자_VO2max'!$B$4:$B$33,MATCH($A4,'대상자_VO2max'!$A$4:$A$33,0))),"ID없음")) | C4: =IF(ISNUMBER(D4),D4,IF($A4="","",IFERROR(IF(INDEX('대상자_VO2max'!$D$4:$D$33,MATCH($A4,'대상자_VO2max'!$A$4:$A$33,0))="","",INDEX('대상자_VO2max'!$D$4:$D$33,MATCH($A4,'대상자_VO2max'!$A$4:$A$33,0))),"ID없음"))) | AO4: =IF(ISNUMBER(G4),G4,"") | AP4: =IF(AND(ISNUMBER(H4),ISNUMBER(I4)),MIN(H4,I4),"") | AQ4: =IF(AND(ISNUMBER(J4),ISNUMBER(K4)),MIN(J4,K4),"") | AR4: =IF(AND(ISNUMBER(L4),ISNUMBER(M4)),IF(N4=1,0,MIN(L4,M4)),"") | AS4: =IF(AND(ISNUMBER(O4),ISNUMBER(P4)),MIN(O4,P4),"") | AT4: =IF(ISNUMBER(Q4),IF(R4=1,0,Q4),"") | AU4: =IF(AND(ISNUMBER(S4),ISNUMBER(T4)),IF(U4=1,0,MIN(S4,T4)),"") | AV4: =IF(COUNT(AO4:AU4)=7,SUM(AO4:AU4),"") | AW4: =IF(ISNUMBER(AV4),--(H4<>I4)+--(J4<>K4)+--(L4<>M4)+--(O4<>P4)+--(S4<>T4),"") | AX4: =IF(ISNUMBER(AV4),COUNT(N4,R4,U4),"") | AY4: =IF(ISNUMBER(Y4),Y4,"") | AZ4: =IF(AND(ISNUMBER(Z4),ISNUMBER(AA4)),MIN(Z4,AA4),"") | BA4: =IF(AND(ISNUMBER(AB4),ISNUMBER(AC4)),MIN(AB4,AC4),"") | BB4: =IF(AND(ISNUMBER(AD4),ISNUMBER(AE4)),IF(AF4=1,0,MIN(AD4,AE4)),"") | BC4: =IF(AND(ISNUMBER(AG4),ISNUMBER(AH4)),MIN(AG4,AH4),"") | BD4: =IF(ISNUMBER(AI4),IF(AJ4=1,0,AI4),"") | BE4: =IF(AND(ISNUMBER(AK4),ISNUMBER(AL4)),IF(AM4=1,0,MIN(AK4,AL4)),"") | BF4: =IF(COUNT(AY4:BE4)=7,SUM(AY4:BE4),"") | BG4: =IF(ISNUMBER(BF4),--(Z4<>AA4)+--(AB4<>AC4)+--(AD4<>AE4)+--(AG4<>AH4)+--(AK4<>AL4),"") | BH4: =IF(ISNUMBER(BF4),COUNT(AF4,AJ4,AM4),"") | BI4: =IF(ISNUMBER(AV4),AV4,IF(ISNUMBER(V4),V4,"")) | BJ4: =IF(ISNUMBER(BF4),BF4,IF(ISNUMBER(AN4),AN4,"")) | BK4: =IF(AND(ISNUMBER(BI4),ISNUMBER(BJ4)),BJ4-BI4,"") | BL4: =IF(ISNUMBER(AV4),"하위항목",IF(ISNUMBER(V4),"SPSS총점","")) | BM4: =IF(ISNUMBER(BF4),"하위항목",IF(ISNUMBER(AN4),"SPSS총점","")) | BN4: =IF($A4="","",IFERROR(IF(ISNUMBER(INDEX('FMS_평가자2'!$AP$4:$AP$33,MATCH($A4,'FMS_평가자2'!$A$4:$A$33,0))),INDEX('FMS_평가자2'!$AP$4:$AP$33,MATCH($A4,'FMS_평가자2'!$A$4:$A$33,0)),""),"")) | BO4: =IF($A4="","",IFERROR(IF(ISNUMBER(INDEX('FMS_평가자2'!$AY$4:$AY$33,MATCH($A4,'FMS_평가자2'!$A$4:$A$33,0))),INDEX('FMS_평가자2'!$AY$4:$AY$33,MATCH($A4,'FMS_평가자2'!$A$4:$A$33,0)),""),"")) | BP4: =IF(AND(ISNUMBER(AV4),ISNUMBER(BN4)),(AV4+BN4)/2,"") | BQ4: =IF(AND(ISNUMBER(BF4),ISNUMBER(BO4)),(BF4+BO4)/2,"") | BR4: =IF(AND(ISNUMBER(BP4),ISNUMBER(BQ4)),BQ4-BP4,"") | BS4: =IF(A4="","",TRIM(IF(B4="ID없음","대상자_VO2max 시트에 없는 ID ","")&IF(LEN(A4)<>LEN(TRIM(A4)),"ID 앞뒤 공백 ","")&IF(COUNTIF($A$4:$A$33,A4)>1,"ID 중복 ","")&IF(AND(B4<>"ID없음",OR(B4="",AND(B4<>1,B4<>2))),"집단 코드 확인(대상자 시트) ","")&IF(AND(B4<>"ID없음",OR(C4="",AND(C4<>0,C4<>1))),"분석포함 코드 확인 ","")&IF(AND(COUNT(G4,H4,I4,J4,K4,L4,M4,O4,P4,Q4,S4,T4)>0,COUNT(G4,H4,I4,J4,K4,L4,M4,O4,P4,Q4,S4,T4)<12),"사전 동작점수 일부 빈칸 ","")&IF(AND(COUNT(Y4,Z4,AA4,AB4,AC4,AD4,AE4,AG4,AH4,AI4,AK4,AL4)>0,COUNT(Y4,Z4,AA4,AB4,AC4,AD4,AE4,AG4,AH4,AI4,AK4,AL4)<12),"사후 동작점수 일부 빈칸 ","")&IF(AND(V4<>"",NOT(ISNUMBER(V4))),"사전 SPSS총점 숫자 아님 ","")&IF(AND(AN4<>"",NOT(ISNUMBER(AN4))),"사후 SPSS총점 숫자 아님 ","")&IF(AND(ISNUMBER(AV4),ISNUMBER(V4)),IF(AV4<>V4,"사전: 계산총점≠SPSS총점 ",""),"")&IF(ISNUMBER(BI4),IF(BI4<>INT(BI4),"사전 총점 정수 아님 ",""),"")&IF(ISNUMBER(BI4),IF(OR(BI4<0,BI4>21),"사전 총점 범위(0–21) 밖 ",""),"")&IF(AND(ISNUMBER(BF4),ISNUMBER(AN4)),IF(BF4<>AN4,"사후: 계산총점≠SPSS총점 ",""),"")&IF(ISNUMBER(BJ4),IF(BJ4<>INT(BJ4),"사후 총점 정수 아님 ",""),"")&IF(ISNUMBER(BJ4),IF(OR(BJ4<0,BJ4>21),"사후 총점 범위(0–21) 밖 ",""),"")&IF(C4=1,IF(OR(NOT(ISNUMBER(BI4)),NOT(ISNUMBER(BJ4))),"분석포함인데 FMS 결측 ",""),"")))
B5: =IF($A5="","",IFERROR(IF(INDEX('대상자_VO2max'!$B$4:$B$33,MATCH($A5,'대상자_VO2max'!$A$4:$A$33,0))="","",INDEX('대상자_VO2max'!$B$4:$B$33,MATCH($A5,'대상자_VO2max'!$A$4:$A$33,0))),"ID없음")) | C5: =IF(ISNUMBER(D5),D5,IF($A5="","",IFERROR(IF(INDEX('대상자_VO2max'!$D$4:$D$33,MATCH($A5,'대상자_VO2max'!$A$4:$A$33,0))="","",INDEX('대상자_VO2max'!$D$4:$D$33,MATCH($A5,'대상자_VO2max'!$A$4:$A$33,0))),"ID없음"))) | AO5: =IF(ISNUMBER(G5),G5,"") | AP5: =IF(AND(ISNUMBER(H5),ISNUMBER(I5)),MIN(H5,I5),"") | AQ5: =IF(AND(ISNUMBER(J5),ISNUMBER(K5)),MIN(J5,K5),"") | AR5: =IF(AND(ISNUMBER(L5),ISNUMBER(M5)),IF(N5=1,0,MIN(L5,M5)),"") | AS5: =IF(AND(ISNUMBER(O5),ISNUMBER(P5)),MIN(O5,P5),"") | AT5: =IF(ISNUMBER(Q5),IF(R5=1,0,Q5),"") | AU5: =IF(AND(ISNUMBER(S5),ISNUMBER(T5)),IF(U5=1,0,MIN(S5,T5)),"") | AV5: =IF(COUNT(AO5:AU5)=7,SUM(AO5:AU5),"") | AW5: =IF(ISNUMBER(AV5),--(H5<>I5)+--(J5<>K5)+--(L5<>M5)+--(O5<>P5)+--(S5<>T5),"") | AX5: =IF(ISNUMBER(AV5),COUNT(N5,R5,U5),"") | AY5: =IF(ISNUMBER(Y5),Y5,"") | AZ5: =IF(AND(ISNUMBER(Z5),ISNUMBER(AA5)),MIN(Z5,AA5),"") | BA5: =IF(AND(ISNUMBER(AB5),ISNUMBER(AC5)),MIN(AB5,AC5),"") | BB5: =IF(AND(ISNUMBER(AD5),ISNUMBER(AE5)),IF(AF5=1,0,MIN(AD5,AE5)),"") | BC5: =IF(AND(ISNUMBER(AG5),ISNUMBER(AH5)),MIN(AG5,AH5),"") | BD5: =IF(ISNUMBER(AI5),IF(AJ5=1,0,AI5),"") | BE5: =IF(AND(ISNUMBER(AK5),ISNUMBER(AL5)),IF(AM5=1,0,MIN(AK5,AL5)),"") | BF5: =IF(COUNT(AY5:BE5)=7,SUM(AY5:BE5),"") | BG5: =IF(ISNUMBER(BF5),--(Z5<>AA5)+--(AB5<>AC5)+--(AD5<>AE5)+--(AG5<>AH5)+--(AK5<>AL5),"") | BH5: =IF(ISNUMBER(BF5),COUNT(AF5,AJ5,AM5),"") | BI5: =IF(ISNUMBER(AV5),AV5,IF(ISNUMBER(V5),V5,"")) | BJ5: =IF(ISNUMBER(BF5),BF5,IF(ISNUMBER(AN5),AN5,"")) | BK5: =IF(AND(ISNUMBER(BI5),ISNUMBER(BJ5)),BJ5-BI5,"") | BL5: =IF(ISNUMBER(AV5),"하위항목",IF(ISNUMBER(V5),"SPSS총점","")) | BM5: =IF(ISNUMBER(BF5),"하위항목",IF(ISNUMBER(AN5),"SPSS총점","")) | BN5: =IF($A5="","",IFERROR(IF(ISNUMBER(INDEX('FMS_평가자2'!$AP$4:$AP$33,MATCH($A5,'FMS_평가자2'!$A$4:$A$33,0))),INDEX('FMS_평가자2'!$AP$4:$AP$33,MATCH($A5,'FMS_평가자2'!$A$4:$A$33,0)),""),"")) | BO5: =IF($A5="","",IFERROR(IF(ISNUMBER(INDEX('FMS_평가자2'!$AY$4:$AY$33,MATCH($A5,'FMS_평가자2'!$A$4:$A$33,0))),INDEX('FMS_평가자2'!$AY$4:$AY$33,MATCH($A5,'FMS_평가자2'!$A$4:$A$33,0)),""),"")) | BP5: =IF(AND(ISNUMBER(AV5),ISNUMBER(BN5)),(AV5+BN5)/2,"") | BQ5: =IF(AND(ISNUMBER(BF5),ISNUMBER(BO5)),(BF5+BO5)/2,"") | BR5: =IF(AND(ISNUMBER(BP5),ISNUMBER(BQ5)),BQ5-BP5,"") | BS5: =IF(A5="","",TRIM(IF(B5="ID없음","대상자_VO2max 시트에 없는 ID ","")&IF(LEN(A5)<>LEN(TRIM(A5)),"ID 앞뒤 공백 ","")&IF(COUNTIF($A$4:$A$33,A5)>1,"ID 중복 ","")&IF(AND(B5<>"ID없음",OR(B5="",AND(B5<>1,B5<>2))),"집단 코드 확인(대상자 시트) ","")&IF(AND(B5<>"ID없음",OR(C5="",AND(C5<>0,C5<>1))),"분석포함 코드 확인 ","")&IF(AND(COUNT(G5,H5,I5,J5,K5,L5,M5,O5,P5,Q5,S5,T5)>0,COUNT(G5,H5,I5,J5,K5,L5,M5,O5,P5,Q5,S5,T5)<12),"사전 동작점수 일부 빈칸 ","")&IF(AND(COUNT(Y5,Z5,AA5,AB5,AC5,AD5,AE5,AG5,AH5,AI5,AK5,AL5)>0,COUNT(Y5,Z5,AA5,AB5,AC5,AD5,AE5,AG5,AH5,AI5,AK5,AL5)<12),"사후 동작점수 일부 빈칸 ","")&IF(AND(V5<>"",NOT(ISNUMBER(V5))),"사전 SPSS총점 숫자 아님 ","")&IF(AND(AN5<>"",NOT(ISNUMBER(AN5))),"사후 SPSS총점 숫자 아님 ","")&IF(AND(ISNUMBER(AV5),ISNUMBER(V5)),IF(AV5<>V5,"사전: 계산총점≠SPSS총점 ",""),"")&IF(ISNUMBER(BI5),IF(BI5<>INT(BI5),"사전 총점 정수 아님 ",""),"")&IF(ISNUMBER(BI5),IF(OR(BI5<0,BI5>21),"사전 총점 범위(0–21) 밖 ",""),"")&IF(AND(ISNUMBER(BF5),ISNUMBER(AN5)),IF(BF5<>AN5,"사후: 계산총점≠SPSS총점 ",""),"")&IF(ISNUMBER(BJ5),IF(BJ5<>INT(BJ5),"사후 총점 정수 아님 ",""),"")&IF(ISNUMBER(BJ5),IF(OR(BJ5<0,BJ5>21),"사후 총점 범위(0–21) 밖 ",""),"")&IF(C5=1,IF(OR(NOT(ISNUMBER(BI5)),NOT(ISNUMBER(BJ5))),"분석포함인데 FMS 결측 ",""),"")))
B6: =IF($A6="","",IFERROR(IF(INDEX('대상자_VO2max'!$B$4:$B$33,MATCH($A6,'대상자_VO2max'!$A$4:$A$33,0))="","",INDEX('대상자_VO2max'!$B$4:$B$33,MATCH($A6,'대상자_VO2max'!$A$4:$A$33,0))),"ID없음")) | C6: =IF(ISNUMBER(D6),D6,IF($A6="","",IFERROR(IF(INDEX('대상자_VO2max'!$D$4:$D$33,MATCH($A6,'대상자_VO2max'!$A$4:$A$33,0))="","",INDEX('대상자_VO2max'!$D$4:$D$33,MATCH($A6,'대상자_VO2max'!$A$4:$A$33,0))),"ID없음"))) | AO6: =IF(ISNUMBER(G6),G6,"") | AP6: =IF(AND(ISNUMBER(H6),ISNUMBER(I6)),MIN(H6,I6),"") | AQ6: =IF(AND(ISNUMBER(J6),ISNUMBER(K6)),MIN(J6,K6),"") | AR6: =IF(AND(ISNUMBER(L6),ISNUMBER(M6)),IF(N6=1,0,MIN(L6,M6)),"") | AS6: =IF(AND(ISNUMBER(O6),ISNUMBER(P6)),MIN(O6,P6),"") | AT6: =IF(ISNUMBER(Q6),IF(R6=1,0,Q6),"") | AU6: =IF(AND(ISNUMBER(S6),ISNUMBER(T6)),IF(U6=1,0,MIN(S6,T6)),"") | AV6: =IF(COUNT(AO6:AU6)=7,SUM(AO6:AU6),"") | AW6: =IF(ISNUMBER(AV6),--(H6<>I6)+--(J6<>K6)+--(L6<>M6)+--(O6<>P6)+--(S6<>T6),"") | AX6: =IF(ISNUMBER(AV6),COUNT(N6,R6,U6),"") | AY6: =IF(ISNUMBER(Y6),Y6,"") | AZ6: =IF(AND(ISNUMBER(Z6),ISNUMBER(AA6)),MIN(Z6,AA6),"") | BA6: =IF(AND(ISNUMBER(AB6),ISNUMBER(AC6)),MIN(AB6,AC6),"") | BB6: =IF(AND(ISNUMBER(AD6),ISNUMBER(AE6)),IF(AF6=1,0,MIN(AD6,AE6)),"") | BC6: =IF(AND(ISNUMBER(AG6),ISNUMBER(AH6)),MIN(AG6,AH6),"") | BD6: =IF(ISNUMBER(AI6),IF(AJ6=1,0,AI6),"") | BE6: =IF(AND(ISNUMBER(AK6),ISNUMBER(AL6)),IF(AM6=1,0,MIN(AK6,AL6)),"") | BF6: =IF(COUNT(AY6:BE6)=7,SUM(AY6:BE6),"") | BG6: =IF(ISNUMBER(BF6),--(Z6<>AA6)+--(AB6<>AC6)+--(AD6<>AE6)+--(AG6<>AH6)+--(AK6<>AL6),"") | BH6: =IF(ISNUMBER(BF6),COUNT(AF6,AJ6,AM6),"") | BI6: =IF(ISNUMBER(AV6),AV6,IF(ISNUMBER(V6),V6,"")) | BJ6: =IF(ISNUMBER(BF6),BF6,IF(ISNUMBER(AN6),AN6,"")) | BK6: =IF(AND(ISNUMBER(BI6),ISNUMBER(BJ6)),BJ6-BI6,"") | BL6: =IF(ISNUMBER(AV6),"하위항목",IF(ISNUMBER(V6),"SPSS총점","")) | BM6: =IF(ISNUMBER(BF6),"하위항목",IF(ISNUMBER(AN6),"SPSS총점","")) | BN6: =IF($A6="","",IFERROR(IF(ISNUMBER(INDEX('FMS_평가자2'!$AP$4:$AP$33,MATCH($A6,'FMS_평가자2'!$A$4:$A$33,0))),INDEX('FMS_평가자2'!$AP$4:$AP$33,MATCH($A6,'FMS_평가자2'!$A$4:$A$33,0)),""),"")) | BO6: =IF($A6="","",IFERROR(IF(ISNUMBER(INDEX('FMS_평가자2'!$AY$4:$AY$33,MATCH($A6,'FMS_평가자2'!$A$4:$A$33,0))),INDEX('FMS_평가자2'!$AY$4:$AY$33,MATCH($A6,'FMS_평가자2'!$A$4:$A$33,0)),""),"")) | BP6: =IF(AND(ISNUMBER(AV6),ISNUMBER(BN6)),(AV6+BN6)/2,"") | BQ6: =IF(AND(ISNUMBER(BF6),ISNUMBER(BO6)),(BF6+BO6)/2,"") | BR6: =IF(AND(ISNUMBER(BP6),ISNUMBER(BQ6)),BQ6-BP6,"") | BS6: =IF(A6="","",TRIM(IF(B6="ID없음","대상자_VO2max 시트에 없는 ID ","")&IF(LEN(A6)<>LEN(TRIM(A6)),"ID 앞뒤 공백 ","")&IF(COUNTIF($A$4:$A$33,A6)>1,"ID 중복 ","")&IF(AND(B6<>"ID없음",OR(B6="",AND(B6<>1,B6<>2))),"집단 코드 확인(대상자 시트) ","")&IF(AND(B6<>"ID없음",OR(C6="",AND(C6<>0,C6<>1))),"분석포함 코드 확인 ","")&IF(AND(COUNT(G6,H6,I6,J6,K6,L6,M6,O6,P6,Q6,S6,T6)>0,COUNT(G6,H6,I6,J6,K6,L6,M6,O6,P6,Q6,S6,T6)<12),"사전 동작점수 일부 빈칸 ","")&IF(AND(COUNT(Y6,Z6,AA6,AB6,AC6,AD6,AE6,AG6,AH6,AI6,AK6,AL6)>0,COUNT(Y6,Z6,AA6,AB6,AC6,AD6,AE6,AG6,AH6,AI6,AK6,AL6)<12),"사후 동작점수 일부 빈칸 ","")&IF(AND(V6<>"",NOT(ISNUMBER(V6))),"사전 SPSS총점 숫자 아님 ","")&IF(AND(AN6<>"",NOT(ISNUMBER(AN6))),"사후 SPSS총점 숫자 아님 ","")&IF(AND(ISNUMBER(AV6),ISNUMBER(V6)),IF(AV6<>V6,"사전: 계산총점≠SPSS총점 ",""),"")&IF(ISNUMBER(BI6),IF(BI6<>INT(BI6),"사전 총점 정수 아님 ",""),"")&IF(ISNUMBER(BI6),IF(OR(BI6<0,BI6>21),"사전 총점 범위(0–21) 밖 ",""),"")&IF(AND(ISNUMBER(BF6),ISNUMBER(AN6)),IF(BF6<>AN6,"사후: 계산총점≠SPSS총점 ",""),"")&IF(ISNUMBER(BJ6),IF(BJ6<>INT(BJ6),"사후 총점 정수 아님 ",""),"")&IF(ISNUMBER(BJ6),IF(OR(BJ6<0,BJ6>21),"사후 총점 범위(0–21) 밖 ",""),"")&IF(C6=1,IF(OR(NOT(ISNUMBER(BI6)),NOT(ISNUMBER(BJ6))),"분석포함인데 FMS 결측 ",""),"")))
B7: =IF($A7="","",IFERROR(IF(INDEX('대상자_VO2max'!$B$4:$B$33,MATCH($A7,'대상자_VO2max'!$A$4:$A$33,0))="","",INDEX('대상자_VO2max'!$B$4:$B$33,MATCH($A7,'대상자_VO2max'!$A$4:$A$33,0))),"ID없음")) | C7: =IF(ISNUMBER(D7),D7,IF($A7="","",IFERROR(IF(INDEX('대상자_VO2max'!$D$4:$D$33,MATCH($A7,'대상자_VO2max'!$A$4:$A$33,0))="","",INDEX('대상자_VO2max'!$D$4:$D$33,MATCH($A7,'대상자_VO2max'!$A$4:$A$33,0))),"ID없음"))) | AO7: =IF(ISNUMBER(G7),G7,"") | AP7: =IF(AND(ISNUMBER(H7),ISNUMBER(I7)),MIN(H7,I7),"") | AQ7: =IF(AND(ISNUMBER(J7),ISNUMBER(K7)),MIN(J7,K7),"") | AR7: =IF(AND(ISNUMBER(L7),ISNUMBER(M7)),IF(N7=1,0,MIN(L7,M7)),"") | AS7: =IF(AND(ISNUMBER(O7),ISNUMBER(P7)),MIN(O7,P7),"") | AT7: =IF(ISNUMBER(Q7),IF(R7=1,0,Q7),"") | AU7: =IF(AND(ISNUMBER(S7),ISNUMBER(T7)),IF(U7=1,0,MIN(S7,T7)),"") | AV7: =IF(COUNT(AO7:AU7)=7,SUM(AO7:AU7),"") | AW7: =IF(ISNUMBER(AV7),--(H7<>I7)+--(J7<>K7)+--(L7<>M7)+--(O7<>P7)+--(S7<>T7),"") | AX7: =IF(ISNUMBER(AV7),COUNT(N7,R7,U7),"") | AY7: =IF(ISNUMBER(Y7),Y7,"") | AZ7: =IF(AND(ISNUMBER(Z7),ISNUMBER(AA7)),MIN(Z7,AA7),"") | BA7: =IF(AND(ISNUMBER(AB7),ISNUMBER(AC7)),MIN(AB7,AC7),"") | BB7: =IF(AND(ISNUMBER(AD7),ISNUMBER(AE7)),IF(AF7=1,0,MIN(AD7,AE7)),"") | BC7: =IF(AND(ISNUMBER(AG7),ISNUMBER(AH7)),MIN(AG7,AH7),"") | BD7: =IF(ISNUMBER(AI7),IF(AJ7=1,0,AI7),"") | BE7: =IF(AND(ISNUMBER(AK7),ISNUMBER(AL7)),IF(AM7=1,0,MIN(AK7,AL7)),"") | BF7: =IF(COUNT(AY7:BE7)=7,SUM(AY7:BE7),"") | BG7: =IF(ISNUMBER(BF7),--(Z7<>AA7)+--(AB7<>AC7)+--(AD7<>AE7)+--(AG7<>AH7)+--(AK7<>AL7),"") | BH7: =IF(ISNUMBER(BF7),COUNT(AF7,AJ7,AM7),"") | BI7: =IF(ISNUMBER(AV7),AV7,IF(ISNUMBER(V7),V7,"")) | BJ7: =IF(ISNUMBER(BF7),BF7,IF(ISNUMBER(AN7),AN7,"")) | BK7: =IF(AND(ISNUMBER(BI7),ISNUMBER(BJ7)),BJ7-BI7,"") | BL7: =IF(ISNUMBER(AV7),"하위항목",IF(ISNUMBER(V7),"SPSS총점","")) | BM7: =IF(ISNUMBER(BF7),"하위항목",IF(ISNUMBER(AN7),"SPSS총점","")) | BN7: =IF($A7="","",IFERROR(IF(ISNUMBER(INDEX('FMS_평가자2'!$AP$4:$AP$33,MATCH($A7,'FMS_평가자2'!$A$4:$A$33,0))),INDEX('FMS_평가자2'!$AP$4:$AP$33,MATCH($A7,'FMS_평가자2'!$A$4:$A$33,0)),""),"")) | BO7: =IF($A7="","",IFERROR(IF(ISNUMBER(INDEX('FMS_평가자2'!$AY$4:$AY$33,MATCH($A7,'FMS_평가자2'!$A$4:$A$33,0))),INDEX('FMS_평가자2'!$AY$4:$AY$33,MATCH($A7,'FMS_평가자2'!$A$4:$A$33,0)),""),"")) | BP7: =IF(AND(ISNUMBER(AV7),ISNUMBER(BN7)),(AV7+BN7)/2,"") | BQ7: =IF(AND(ISNUMBER(BF7),ISNUMBER(BO7)),(BF7+BO7)/2,"") | BR7: =IF(AND(ISNUMBER(BP7),ISNUMBER(BQ7)),BQ7-BP7,"") | BS7: =IF(A7="","",TRIM(IF(B7="ID없음","대상자_VO2max 시트에 없는 ID ","")&IF(LEN(A7)<>LEN(TRIM(A7)),"ID 앞뒤 공백 ","")&IF(COUNTIF($A$4:$A$33,A7)>1,"ID 중복 ","")&IF(AND(B7<>"ID없음",OR(B7="",AND(B7<>1,B7<>2))),"집단 코드 확인(대상자 시트) ","")&IF(AND(B7<>"ID없음",OR(C7="",AND(C7<>0,C7<>1))),"분석포함 코드 확인 ","")&IF(AND(COUNT(G7,H7,I7,J7,K7,L7,M7,O7,P7,Q7,S7,T7)>0,COUNT(G7,H7,I7,J7,K7,L7,M7,O7,P7,Q7,S7,T7)<12),"사전 동작점수 일부 빈칸 ","")&IF(AND(COUNT(Y7,Z7,AA7,AB7,AC7,AD7,AE7,AG7,AH7,AI7,AK7,AL7)>0,COUNT(Y7,Z7,AA7,AB7,AC7,AD7,AE7,AG7,AH7,AI7,AK7,AL7)<12),"사후 동작점수 일부 빈칸 ","")&IF(AND(V7<>"",NOT(ISNUMBER(V7))),"사전 SPSS총점 숫자 아님 ","")&IF(AND(AN7<>"",NOT(ISNUMBER(AN7))),"사후 SPSS총점 숫자 아님 ","")&IF(AND(ISNUMBER(AV7),ISNUMBER(V7)),IF(AV7<>V7,"사전: 계산총점≠SPSS총점 ",""),"")&IF(ISNUMBER(BI7),IF(BI7<>INT(BI7),"사전 총점 정수 아님 ",""),"")&IF(ISNUMBER(BI7),IF(OR(BI7<0,BI7>21),"사전 총점 범위(0–21) 밖 ",""),"")&IF(AND(ISNUMBER(BF7),ISNUMBER(AN7)),IF(BF7<>AN7,"사후: 계산총점≠SPSS총점 ",""),"")&IF(ISNUMBER(BJ7),IF(BJ7<>INT(BJ7),"사후 총점 정수 아님 ",""),"")&IF(ISNUMBER(BJ7),IF(OR(BJ7<0,BJ7>21),"사후 총점 범위(0–21) 밖 ",""),"")&IF(C7=1,IF(OR(NOT(ISNUMBER(BI7)),NOT(ISNUMBER(BJ7))),"분석포함인데 FMS 결측 ",""),"")))
