Workbook

Sheet data
A1: id | B1: group | C1: floor | D1: incl | E1: excl_rsn | F1: excl_txt | G1: excl_when | H1: attend | I1: band_fin | J1: age | K1: height | L1: weight | M1: date_pre | N1: rater_pre | O1: kfes01_pre | P1: kfes02_pre | Q1: kfes03_pre | R1: kfes04_pre | S1: kfes05_pre | T1: kfes06_pre | U1: kfes07_pre | V1: kfes08_pre | W1: kfes09_pre | X1: kfes10_pre | Y1: kfes11_pre | Z1: kfes12_pre | AA1: kfes13_pre | AB1: kfes14_pre | AC1: kfes15_pre | AD1: kfes16_pre | AE1: chair_pre | AF1: curl_pre | AG1: step_pre | AH1: bs1_pre | AI1: bs2_pre | AJ1: sr1_pre | AK1: sr2_pre | AL1: tug1_pre | AM1: tug2_pre | AN1: date_post | AO1: rater_post | AP1: kfes01_post | AQ1: kfes02_post | AR1: kfes03_post | AS1: kfes04_post | AT1: kfes05_post | AU1: kfes06_post | AV1: kfes07_post | AW1: kfes08_post | AX1: kfes09_post | AY1: kfes10_post | AZ1: kfes11_post | BA1: kfes12_post | BB1: kfes13_post | BC1: kfes14_post | BD1: kfes15_post | BE1: kfes16_post | BF1: chair_post | BG1: curl_post | BH1: step_post | BI1: bs1_post | BJ1: bs2_post | BK1: sr1_post | BL1: sr2_post | BM1: tug1_post | BN1: tug2_post | BO1: note

Sheet 코드북
A1: 변수명 | B1: 설명 | C1: 구역 | D1: 종류 | E1: 입력값·코드 | F1: 허용 범위 | G1: 기록 방법
A2: id | B2: 대상자 번호(기록지 번호) | C2: 기본 | D2: 정수 | F2: 1~99 | G2: 기록지에 적힌 번호
A3: group | B3: 집단 | C3: 기본 | D3: 코드 | E3: 1=실험집단; 2=통제집단 | G3: 1=실험, 2=통제
A4: floor | B4: 이용 층 | C4: 기본 | D4: 코드 | E4: 2=2층; 4=4층 | G4: 2 또는 4
A5: incl | B5: 최종 분석 포함 | C5: 기본 | D5: 코드 | E5: 1=최종 분석 포함; 0=제외 | G5: 1=포함, 0=제외
A6: excl_rsn | B6: 제외 사유 | C6: 기본 | D6: 코드 | E6: 1=출석 미달; 2=건강상 이유; 3=사후검사 불참; 4=참여 철회; 5=기타 | G6: 제외자만. 1 출석 미달, 2 건강상 이유, 3 사후검사 불참, 4 참여 철회, 5 기타
A7: excl_txt | B7: 제외 사유 상세 | C7: 기본 | D7: 문자 | G7: 제외자만. 예: 무릎 통증으로 4주차부터 불참
A8: excl_when | B8: 제외 시점 | C8: 기본 | D8: 코드 | E8: 1=사전검사 후 중재 시작 전; 2=중재 중; 3=사후검사 전 | G8: 제외자만. 1 사전검사 후 중재 시작 전, 2 중재 중, 3 사후검사 전
A9: attend | B9: 출석 횟수(24회 중) | C9: 기본 | D9: 정수 | F9: 0~24 | G9: 실험집단만. 출석부 기준
A10: band_fin | B10: 8주차 최종 밴드 색상 | C10: 기본 | D10: 문자 | G10: 실험집단만. 예: 빨강
A11: age | B11: 나이(만, 세) | C11: 기본 | D11: 정수 | F11: 60~105 | G11: 만 나이
A12: height | B12: 신장(cm) | C12: 기본 | D12: 숫자(소수 1자리까지) | F12: 120~190 | G12: cm, 기록지 그대로
A13: weight | B13: 체중(kg) | C13: 기본 | D13: 숫자(소수 1자리까지) | F13: 25~120 | G13: kg, 기록지 그대로
A14: date_pre | B14: 사전검사 날짜 | C14: 사전 | D14: 날짜 | G14: YYYY-MM-DD
A15: rater_pre | B15: 사전 측정자 | C15: 사전 | D15: 문자 | G15: 이름 또는 기호(예: A)
A16: kfes01_pre | B16: KFES-I 1번 문항 사전 | C16: 사전 | D16: 정수 | F16: 1~4 | G16: 1 전혀 걱정 안 함 ~ 4 매우 걱정
A17: kfes02_pre | B17: KFES-I 2번 문항 사전 | C17: 사전 | D17: 정수 | F17: 1~4 | G17: 1 전혀 걱정 안 함 ~ 4 매우 걱정
A18: kfes03_pre | B18: KFES-I 3번 문항 사전 | C18: 사전 | D18: 정수 | F18: 1~4 | G18: 1 전혀 걱정 안 함 ~ 4 매우 걱정
A19: kfes04_pre | B19: KFES-I 4번 문항 사전 | C19: 사전 | D19: 정수 | F19: 1~4 | G19: 1 전혀 걱정 안 함 ~ 4 매우 걱정
A20: kfes05_pre | B20: KFES-I 5번 문항 사전 | C20: 사전 | D20: 정수 | F20: 1~4 | G20: 1 전혀 걱정 안 함 ~ 4 매우 걱정
A21: kfes06_pre | B21: KFES-I 6번 문항 사전 | C21: 사전 | D21: 정수 | F21: 1~4 | G21: 1 전혀 걱정 안 함 ~ 4 매우 걱정
A22: kfes07_pre | B22: KFES-I 7번 문항 사전 | C22: 사전 | D22: 정수 | F22: 1~4 | G22: 1 전혀 걱정 안 함 ~ 4 매우 걱정
A23: kfes08_pre | B23: KFES-I 8번 문항 사전 | C23: 사전 | D23: 정수 | F23: 1~4 | G23: 1 전혀 걱정 안 함 ~ 4 매우 걱정
A24: kfes09_pre | B24: KFES-I 9번 문항 사전 | C24: 사전 | D24: 정수 | F24: 1~4 | G24: 1 전혀 걱정 안 함 ~ 4 매우 걱정
A25: kfes10_pre | B25: KFES-I 10번 문항 사전 | C25: 사전 | D25: 정수 | F25: 1~4 | G25: 1 전혀 걱정 안 함 ~ 4 매우 걱정
A26: kfes11_pre | B26: KFES-I 11번 문항 사전 | C26: 사전 | D26: 정수 | F26: 1~4 | G26: 1 전혀 걱정 안 함 ~ 4 매우 걱정
A27: kfes12_pre | B27: KFES-I 12번 문항 사전 | C27: 사전 | D27: 정수 | F27: 1~4 | G27: 1 전혀 걱정 안 함 ~ 4 매우 걱정
... A40: tug2_pre | B40: 2.44 m 갔다 오기 사전 2회(초) | C40: 사전 | D40: 숫자(소수 2자리까지) | F40: 2~60 | G40: 2회 기록이 없으면 비움
A41: date_post | B41: 사후검사 날짜 | C41: 사후 | D41: 날짜 | G41: YYYY-MM-DD
A42: rater_post | B42: 사후 측정자 | C42: 사후 | D42: 문자 | G42: 이름 또는 기호(예: A)
A43: kfes01_post | B43: KFES-I 1번 문항 사후 | C43: 사후 | D43: 정수 | F43: 1~4 | G43: 1 전혀 걱정 안 함 ~ 4 매우 걱정
A44: kfes02_post | B44: KFES-I 2번 문항 사후 | C44: 사후 | D44: 정수 | F44: 1~4 | G44: 1 전혀 걱정 안 함 ~ 4 매우 걱정
A45: kfes03_post | B45: KFES-I 3번 문항 사후 | C45: 사후 | D45: 정수 | F45: 1~4 | G45: 1 전혀 걱정 안 함 ~ 4 매우 걱정
A46: kfes04_post | B46: KFES-I 4번 문항 사후 | C46: 사후 | D46: 정수 | F46: 1~4 | G46: 1 전혀 걱정 안 함 ~ 4 매우 걱정
A47: kfes05_post | B47: KFES-I 5번 문항 사후 | C47: 사후 | D47: 정수 | F47: 1~4 | G47: 1 전혀 걱정 안 함 ~ 4 매우 걱정
A48: kfes06_post | B48: KFES-I 6번 문항 사후 | C48: 사후 | D48: 정수 | F48: 1~4 | G48: 1 전혀 걱정 안 함 ~ 4 매우 걱정
A49: kfes07_post | B49: KFES-I 7번 문항 사후 | C49: 사후 | D49: 정수 | F49: 1~4 | G49: 1 전혀 걱정 안 함 ~ 4 매우 걱정
A50: kfes08_post | B50: KFES-I 8번 문항 사후 | C50: 사후 | D50: 정수 | F50: 1~4 | G50: 1 전혀 걱정 안 함 ~ 4 매우 걱정
A51: kfes09_post | B51: KFES-I 9번 문항 사후 | C51: 사후 | D51: 정수 | F51: 1~4 | G51: 1 전혀 걱정 안 함 ~ 4 매우 걱정
A52: kfes10_post | B52: KFES-I 10번 문항 사후 | C52: 사후 | D52: 정수 | F52: 1~4 | G52: 1 전혀 걱정 안 함 ~ 4 매우 걱정
...

Sheet 입력점검
A1: id | B1: group | C1: incl | D1: KFES 사전 문항 수 | E1: KFES 사후 문항 수 | F1: KFES 사전 총점 | G1: KFES 사후 총점 | H1: 등뒤 사전 최고 | I1: 등뒤 사후 최고 | J1: 앉아 사전 최고 | K1: 앉아 사후 최고 | L1: 2.44 사전 최고 | M1: 2.44 사후 최고 | N1: 사전=사후 같은 항목 수(7개 중) | O1: 포함 대상 빈칸 수
A2: =IF(data!A2="","",data!A2) | B2: =IF(data!B2="","",data!B2) | C2: =IF(data!D2="","",data!D2) | D2: =IF(data!A2="","",COUNT(data!O2:AD2)) | E2: =IF(data!A2="","",COUNT(data!AP2:BE2)) | F2: =IF(data!A2="","",IF(COUNT(data!O2:AD2)=16,SUM(data!O2:AD2),"")) | G2: =IF(data!A2="","",IF(COUNT(data!AP2:BE2)=16,SUM(data!AP2:BE2),"")) | H2: =IF(COUNT(data!AH2,data!AI2)=0,"",MAX(data!AH2,data!AI2)) | I2: =IF(COUNT(data!BI2,data!BJ2)=0,"",MAX(data!BI2,data!BJ2)) | J2: =IF(COUNT(data!AJ2,data!AK2)=0,"",MAX(data!AJ2,data!AK2)) | K2: =IF(COUNT(data!BK2,data!BL2)=0,"",MAX(data!BK2,data!BL2)) | L2: =IF(COUNT(data!AL2,data!AM2)=0,"",MIN(data!AL2,data!AM2)) | M2: =IF(COUNT(data!BM2,data!BN2)=0,"",MIN(data!BM2,data!BN2)) | N2: =IF(data!A2="","",IF(OR(F2="",G2=""),0,--(F2=G2))+IF(OR(data!AE2="",data!BF2=""),0,--(data!AE2=data!BF2))+IF(OR(data!AF2="",data!BG2=""),0,--(data!AF2=data!BG2))+IF(OR(data!AG2="",data!BH2=""),0,--(data!AG2=data!BH2))+IF(OR(H2="",I2=""),0,--(H2=I2))+IF(OR(J2="",K2=""),0,--(J2=K2))+IF(OR(L2="",M2=""),0,--(L2=M2))) | O2: =IF(data!D2<>1,"",--(data!O2="")+--(data!P2="")+--(data!Q2="")+--(data!R2="")+--(data!S2="")+--(data!T2="")+--(data!U2="")+--(data!V2="")+--(data!W2="")+--(data!X2="")+--(data!Y2="")+--(data!Z2="")+--(data!AA2="")+--(data!AB2="")+--(data!AC2="")+--(data!AD2="")+--(data!AE2="")+--(data!AF2="")+--(data!AG2="")+--(data!AH2="")+--(data!AJ2="")+--(data!AL2="")+--(data!AP2="")+--(data!AQ2="")+--(data!AR2="")+--(data!AS2="")+--(data!AT2="")+--(data!AU2="")+--(data!AV2="")+--(data!AW2="")+--(data!AX2="")+--(data!AY2="")+--(data!AZ2="")+--(data!BA2="")+--(data!BB2="")+--(data!BC2="")+--(data!BD2="")+--(data!BE2="")+--(data!BF2="")+--(data!BG2="")+--(data!BH2="")+--(data!BI2="")+--(data!BK2="")+--(data!BM2="")+--(data!J2="")+--(data!K2="")+--(data!L2=""))
A3: =IF(data!A3="","",data!A3) | B3: =IF(data!B3="","",data!B3) | C3: =IF(data!D3="","",data!D3) | D3: =IF(data!A3="","",COUNT(data!O3:AD3)) | E3: =IF(data!A3="","",COUNT(data!AP3:BE3)) | F3: =IF(data!A3="","",IF(COUNT(data!O3:AD3)=16,SUM(data!O3:AD3),"")) | G3: =IF(data!A3="","",IF(COUNT(data!AP3:BE3)=16,SUM(data!AP3:BE3),"")) | H3: =IF(COUNT(data!AH3,data!AI3)=0,"",MAX(data!AH3,data!AI3)) | I3: =IF(COUNT(data!BI3,data!BJ3)=0,"",MAX(data!BI3,data!BJ3)) | J3: =IF(COUNT(data!AJ3,data!AK3)=0,"",MAX(data!AJ3,data!AK3)) | K3: =IF(COUNT(data!BK3,data!BL3)=0,"",MAX(data!BK3,data!BL3)) | L3: =IF(COUNT(data!AL3,data!AM3)=0,"",MIN(data!AL3,data!AM3)) | M3: =IF(COUNT(data!BM3,data!BN3)=0,"",MIN(data!BM3,data!BN3)) | N3: =IF(data!A3="","",IF(OR(F3="",G3=""),0,--(F3=G3))+IF(OR(data!AE3="",data!BF3=""),0,--(data!AE3=data!BF3))+IF(OR(data!AF3="",data!BG3=""),0,--(data!AF3=data!BG3))+IF(OR(data!AG3="",data!BH3=""),0,--(data!AG3=data!BH3))+IF(OR(H3="",I3=""),0,--(H3=I3))+IF(OR(J3="",K3=""),0,--(J3=K3))+IF(OR(L3="",M3=""),0,--(L3=M3))) | O3: =IF(data!D3<>1,"",--(data!O3="")+--(data!P3="")+--(data!Q3="")+--(data!R3="")+--(data!S3="")+--(data!T3="")+--(data!U3="")+--(data!V3="")+--(data!W3="")+--(data!X3="")+--(data!Y3="")+--(data!Z3="")+--(data!AA3="")+--(data!AB3="")+--(data!AC3="")+--(data!AD3="")+--(data!AE3="")+--(data!AF3="")+--(data!AG3="")+--(data!AH3="")+--(data!AJ3="")+--(data!AL3="")+--(data!AP3="")+--(data!AQ3="")+--(data!AR3="")+--(data!AS3="")+--(data!AT3="")+--(data!AU3="")+--(data!AV3="")+--(data!AW3="")+--(data!AX3="")+--(data!AY3="")+--(data!AZ3="")+--(data!BA3="")+--(data!BB3="")+--(data!BC3="")+--(data!BD3="")+--(data!BE3="")+--(data!BF3="")+--(data!BG3="")+--(data!BH3="")+--(data!BI3="")+--(data!BK3="")+--(data!BM3="")+--(data!J3="")+--(data!K3="")+--(data!L3=""))
A4: =IF(data!A4="","",data!A4) | B4: =IF(data!B4="","",data!B4) | C4: =IF(data!D4="","",data!D4) | D4: =IF(data!A4="","",COUNT(data!O4:AD4)) | E4: =IF(data!A4="","",COUNT(data!AP4:BE4)) | F4: =IF(data!A4="","",IF(COUNT(data!O4:AD4)=16,SUM(data!O4:AD4),"")) | G4: =IF(data!A4="","",IF(COUNT(data!AP4:BE4)=16,SUM(data!AP4:BE4),"")) | H4: =IF(COUNT(data!AH4,data!AI4)=0,"",MAX(data!AH4,data!AI4)) | I4: =IF(COUNT(data!BI4,data!BJ4)=0,"",MAX(data!BI4,data!BJ4)) | J4: =IF(COUNT(data!AJ4,data!AK4)=0,"",MAX(data!AJ4,data!AK4)) | K4: =IF(COUNT(data!BK4,data!BL4)=0,"",MAX(data!BK4,data!BL4)) | L4: =IF(COUNT(data!AL4,data!AM4)=0,"",MIN(data!AL4,data!AM4)) | M4: =IF(COUNT(data!BM4,data!BN4)=0,"",MIN(data!BM4,data!BN4)) | N4: =IF(data!A4="","",IF(OR(F4="",G4=""),0,--(F4=G4))+IF(OR(data!AE4="",data!BF4=""),0,--(data!AE4=data!BF4))+IF(OR(data!AF4="",data!BG4=""),0,--(data!AF4=data!BG4))+IF(OR(data!AG4="",data!BH4=""),0,--(data!AG4=data!BH4))+IF(OR(H4="",I4=""),0,--(H4=I4))+IF(OR(J4="",K4=""),0,--(J4=K4))+IF(OR(L4="",M4=""),0,--(L4=M4))) | O4: =IF(data!D4<>1,"",--(data!O4="")+--(data!P4="")+--(data!Q4="")+--(data!R4="")+--(data!S4="")+--(data!T4="")+--(data!U4="")+--(data!V4="")+--(data!W4="")+--(data!X4="")+--(data!Y4="")+--(data!Z4="")+--(data!AA4="")+--(data!AB4="")+--(data!AC4="")+--(data!AD4="")+--(data!AE4="")+--(data!AF4="")+--(data!AG4="")+--(data!AH4="")+--(data!AJ4="")+--(data!AL4="")+--(data!AP4="")+--(data!AQ4="")+--(data!AR4="")+--(data!AS4="")+--(data!AT4="")+--(data!AU4="")+--(data!AV4="")+--(data!AW4="")+--(data!AX4="")+--(data!AY4="")+--(data!AZ4="")+--(data!BA4="")+--(data!BB4="")+--(data!BC4="")+--(data!BD4="")+--(data!BE4="")+--(data!BF4="")+--(data!BG4="")+--(data!BH4="")+--(data!BI4="")+--(data!BK4="")+--(data!BM4="")+--(data!J4="")+--(data!K4="")+--(data!L4=""))
A5: =IF(data!A5="","",data!A5) | B5: =IF(data!B5="","",data!B5) | C5: =IF(data!D5="","",data!D5) | D5: =IF(data!A5="","",COUNT(data!O5:AD5)) | E5: =IF(data!A5="","",COUNT(data!AP5:BE5)) | F5: =IF(data!A5="","",IF(COUNT(data!O5:AD5)=16,SUM(data!O5:AD5),"")) | G5: =IF(data!A5="","",IF(COUNT(data!AP5:BE5)=16,SUM(data!AP5:BE5),"")) | H5: =IF(COUNT(data!AH5,data!AI5)=0,"",MAX(data!AH5,data!AI5)) | I5: =IF(COUNT(data!BI5,data!BJ5)=0,"",MAX(data!BI5,data!BJ5)) | J5: =IF(COUNT(data!AJ5,data!AK5)=0,"",MAX(data!AJ5,data!AK5)) | K5: =IF(COUNT(data!BK5,data!BL5)=0,"",MAX(data!BK5,data!BL5)) | L5: =IF(COUNT(data!AL5,data!AM5)=0,"",MIN(data!AL5,data!AM5)) | M5: =IF(COUNT(data!BM5,data!BN5)=0,"",MIN(data!BM5,data!BN5)) | N5: =IF(data!A5="","",IF(OR(F5="",G5=""),0,--(F5=G5))+IF(OR(data!AE5="",data!BF5=""),0,--(data!AE5=data!BF5))+IF(OR(data!AF5="",data!BG5=""),0,--(data!AF5=data!BG5))+IF(OR(data!AG5="",data!BH5=""),0,--(data!AG5=data!BH5))+IF(OR(H5="",I5=""),0,--(H5=I5))+IF(OR(J5="",K5=""),0,--(J5=K5))+IF(OR(L5="",M5=""),0,--(L5=M5))) | O5: =IF(data!D5<>1,"",--(data!O5="")+--(data!P5="")+--(data!Q5="")+--(data!R5="")+--(data!S5="")+--(data!T5="")+--(data!U5="")+--(data!V5="")+--(data!W5="")+--(data!X5="")+--(data!Y5="")+--(data!Z5="")+--(data!AA5="")+--(data!AB5="")+--(data!AC5="")+--(data!AD5="")+--(data!AE5="")+--(data!AF5="")+--(data!AG5="")+--(data!AH5="")+--(data!AJ5="")+--(data!AL5="")+--(data!AP5="")+--(data!AQ5="")+--(data!AR5="")+--(data!AS5="")+--(data!AT5="")+--(data!AU5="")+--(data!AV5="")+--(data!AW5="")+--(data!AX5="")+--(data!AY5="")+--(data!AZ5="")+--(data!BA5="")+--(data!BB5="")+--(data!BC5="")+--(data!BD5="")+--(data!BE5="")+--(data!BF5="")+--(data!BG5="")+--(data!BH5="")+--(data!BI5="")+--(data!BK5="")+--(data!BM5="")+--(data!J5="")+--(data!K5="")+--(data!L5=""))
A6: =IF(data!A6="","",data!A6) | B6: =IF(data!B6="","",data!B6) | C6: =IF(data!D6="","",data!D6) | D6: =IF(data!A6="","",COUNT(data!O6:AD6)) | E6: =IF(data!A6="","",COUNT(data!AP6:BE6)) | F6: =IF(data!A6="","",IF(COUNT(data!O6:AD6)=16,SUM(data!O6:AD6),"")) | G6: =IF(data!A6="","",IF(COUNT(data!AP6:BE6)=16,SUM(data!AP6:BE6),"")) | H6: =IF(COUNT(data!AH6,data!AI6)=0,"",MAX(data!AH6,data!AI6)) | I6: =IF(COUNT(data!BI6,data!BJ6)=0,"",MAX(data!BI6,data!BJ6)) | J6: =IF(COUNT(data!AJ6,data!AK6)=0,"",MAX(data!AJ6,data!AK6)) | K6: =IF(COUNT(data!BK6,data!BL6)=0,"",MAX(data!BK6,data!BL6)) | L6: =IF(COUNT(data!AL6,data!AM6)=0,"",MIN(data!AL6,data!AM6)) | M6: =IF(COUNT(data!BM6,data!BN6)=0,"",MIN(data!BM6,data!BN6)) | N6: =IF(data!A6="","",IF(OR(F6="",G6=""),0,--(F6=G6))+IF(OR(data!AE6="",data!BF6=""),0,--(data!AE6=data!BF6))+IF(OR(data!AF6="",data!BG6=""),0,--(data!AF6=data!BG6))+IF(OR(data!AG6="",data!BH6=""),0,--(data!AG6=data!BH6))+IF(OR(H6="",I6=""),0,--(H6=I6))+IF(OR(J6="",K6=""),0,--(J6=K6))+IF(OR(L6="",M6=""),0,--(L6=M6))) | O6: =IF(data!D6<>1,"",--(data!O6="")+--(data!P6="")+--(data!Q6="")+--(data!R6="")+--(data!S6="")+--(data!T6="")+--(data!U6="")+--(data!V6="")+--(data!W6="")+--(data!X6="")+--(data!Y6="")+--(data!Z6="")+--(data!AA6="")+--(data!AB6="")+--(data!AC6="")+--(data!AD6="")+--(data!AE6="")+--(data!AF6="")+--(data!AG6="")+--(data!AH6="")+--(data!AJ6="")+--(data!AL6="")+--(data!AP6="")+--(data!AQ6="")+--(data!AR6="")+--(data!AS6="")+--(data!AT6="")+--(data!AU6="")+--(data!AV6="")+--(data!AW6="")+--(data!AX6="")+--(data!AY6="")+--(data!AZ6="")+--(data!BA6="")+--(data!BB6="")+--(data!BC6="")+--(data!BD6="")+--(data!BE6="")+--(data!BF6="")+--(data!BG6="")+--(data!BH6="")+--(data!BI6="")+--(data!BK6="")+--(data!BM6="")+--(data!J6="")+--(data!K6="")+--(data!L6=""))
A7: =IF(data!A7="","",data!A7) | B7: =IF(data!B7="","",data!B7) | C7: =IF(data!D7="","",data!D7) | D7: =IF(data!A7="","",COUNT(data!O7:AD7)) | E7: =IF(data!A7="","",COUNT(data!AP7:BE7)) | F7: =IF(data!A7="","",IF(COUNT(data!O7:AD7)=16,SUM(data!O7:AD7),"")) | G7: =IF(data!A7="","",IF(COUNT(data!AP7:BE7)=16,SUM(data!AP7:BE7),"")) | H7: =IF(COUNT(data!AH7,data!AI7)=0,"",MAX(data!AH7,data!AI7)) | I7: =IF(COUNT(data!BI7,data!BJ7)=0,"",MAX(data!BI7,data!BJ7)) | J7: =IF(COUNT(data!AJ7,data!AK7)=0,"",MAX(data!AJ7,data!AK7)) | K7: =IF(COUNT(data!BK7,data!BL7)=0,"",MAX(data!BK7,data!BL7)) | L7: =IF(COUNT(data!AL7,data!AM7)=0,"",MIN(data!AL7,data!AM7)) | M7: =IF(COUNT(data!BM7,data!BN7)=0,"",MIN(data!BM7,data!BN7)) | N7: =IF(data!A7="","",IF(OR(F7="",G7=""),0,--(F7=G7))+IF(OR(data!AE7="",data!BF7=""),0,--(data!AE7=data!BF7))+IF(OR(data!AF7="",data!BG7=""),0,--(data!AF7=data!BG7))+IF(OR(data!AG7="",data!BH7=""),0,--(data!AG7=data!BH7))+IF(OR(H7="",I7=""),0,--(H7=I7))+IF(OR(J7="",K7=""),0,--(J7=K7))+IF(OR(L7="",M7=""),0,--(L7=M7))) | O7: =IF(data!D7<>1,"",--(data!O7="")+--(data!P7="")+--(data!Q7="")+--(data!R7="")+--(data!S7="")+--(data!T7="")+--(data!U7="")+--(data!V7="")+--(data!W7="")+--(data!X7="")+--(data!Y7="")+--(data!Z7="")+--(data!AA7="")+--(data!AB7="")+--(data!AC7="")+--(data!AD7="")+--(data!AE7="")+--(data!AF7="")+--(data!AG7="")+--(data!AH7="")+--(data!AJ7="")+--(data!AL7="")+--(data!AP7="")+--(data!AQ7="")+--(data!AR7="")+--(data!AS7="")+--(data!AT7="")+--(data!AU7="")+--(data!AV7="")+--(data!AW7="")+--(data!AX7="")+--(data!AY7="")+--(data!AZ7="")+--(data!BA7="")+--(data!BB7="")+--(data!BC7="")+--(data!BD7="")+--(data!BE7="")+--(data!BF7="")+--(data!BG7="")+--(data!BH7="")+--(data!BI7="")+--(data!BK7="")+--(data!BM7="")+--(data!J7="")+--(data!K7="")+--(data!L7=""))
A8: =IF(data!A8="","",data!A8) | B8: =IF(data!B8="","",data!B8) | C8: =IF(data!D8="","",data!D8) | D8: =IF(data!A8="","",COUNT(data!O8:AD8)) | E8: =IF(data!A8="","",COUNT(data!AP8:BE8)) | F8: =IF(data!A8="","",IF(COUNT(data!O8:AD8)=16,SUM(data!O8:AD8),"")) | G8: =IF(data!A8="","",IF(COUNT(data!AP8:BE8)=16,SUM(data!AP8:BE8),"")) | H8: =IF(COUNT(data!AH8,data!AI8)=0,"",MAX(data!AH8,data!AI8)) | I8: =IF(COUNT(data!BI8,data!BJ8)=0,"",MAX(data!BI8,data!BJ8)) | J8: =IF(COUNT(data!AJ8,data!AK8)=0,"",MAX(data!AJ8,data!AK8)) | K8: =IF(COUNT(data!BK8,data!BL8)=0,"",MAX(data!BK8,data!BL8)) | L8: =IF(COUNT(data!AL8,data!AM8)=0,"",MIN(data!AL8,data!AM8)) | M8: =IF(COUNT(data!BM8,data!BN8)=0,"",MIN(data!BM8,data!BN8)) | N8: =IF(data!A8="","",IF(OR(F8="",G8=""),0,--(F8=G8))+IF(OR(data!AE8="",data!BF8=""),0,--(data!AE8=data!BF8))+IF(OR(data!AF8="",data!BG8=""),0,--(data!AF8=data!BG8))+IF(OR(data!AG8="",data!BH8=""),0,--(data!AG8=data!BH8))+IF(OR(H8="",I8=""),0,--(H8=I8))+IF(OR(J8="",K8=""),0,--(J8=K8))+IF(OR(L8="",M8=""),0,--(L8=M8))) | O8: =IF(data!D8<>1,"",--(data!O8="")+--(data!P8="")+--(data!Q8="")+--(data!R8="")+--(data!S8="")+--(data!T8="")+--(data!U8="")+--(data!V8="")+--(data!W8="")+--(data!X8="")+--(data!Y8="")+--(data!Z8="")+--(data!AA8="")+--(data!AB8="")+--(data!AC8="")+--(data!AD8="")+--(data!AE8="")+--(data!AF8="")+--(data!AG8="")+--(data!AH8="")+--(data!AJ8="")+--(data!AL8="")+--(data!AP8="")+--(data!AQ8="")+--(data!AR8="")+--(data!AS8="")+--(data!AT8="")+--(data!AU8="")+--(data!AV8="")+--(data!AW8="")+--(data!AX8="")+--(data!AY8="")+--(data!AZ8="")+--(data!BA8="")+--(data!BB8="")+--(data!BC8="")+--(data!BD8="")+--(data!BE8="")+--(data!BF8="")+--(data!BG8="")+--(data!BH8="")+--(data!BI8="")+--(data!BK8="")+--(data!BM8="")+--(data!J8="")+--(data!K8="")+--(data!L8=""))
A9: =IF(data!A9="","",data!A9) | B9: =IF(data!B9="","",data!B9) | C9: =IF(data!D9="","",data!D9) | D9: =IF(data!A9="","",COUNT(data!O9:AD9)) | E9: =IF(data!A9="","",COUNT(data!AP9:BE9)) | F9: =IF(data!A9="","",IF(COUNT(data!O9:AD9)=16,SUM(data!O9:AD9),"")) | G9: =IF(data!A9="","",IF(COUNT(data!AP9:BE9)=16,SUM(data!AP9:BE9),"")) | H9: =IF(COUNT(data!AH9,data!AI9)=0,"",MAX(data!AH9,data!AI9)) | I9: =IF(COUNT(data!BI9,data!BJ9)=0,"",MAX(data!BI9,data!BJ9)) | J9: =IF(COUNT(data!AJ9,data!AK9)=0,"",MAX(data!AJ9,data!AK9)) | K9: =IF(COUNT(data!BK9,data!BL9)=0,"",MAX(data!BK9,data!BL9)) | L9: =IF(COUNT(data!AL9,data!AM9)=0,"",MIN(data!AL9,data!AM9)) | M9: =IF(COUNT(data!BM9,data!BN9)=0,"",MIN(data!BM9,data!BN9)) | N9: =IF(data!A9="","",IF(OR(F9="",G9=""),0,--(F9=G9))+IF(OR(data!AE9="",data!BF9=""),0,--(data!AE9=data!BF9))+IF(OR(data!AF9="",data!BG9=""),0,--(data!AF9=data!BG9))+IF(OR(data!AG9="",data!BH9=""),0,--(data!AG9=data!BH9))+IF(OR(H9="",I9=""),0,--(H9=I9))+IF(OR(J9="",K9=""),0,--(J9=K9))+IF(OR(L9="",M9=""),0,--(L9=M9))) | O9: =IF(data!D9<>1,"",--(data!O9="")+--(data!P9="")+--(data!Q9="")+--(data!R9="")+--(data!S9="")+--(data!T9="")+--(data!U9="")+--(data!V9="")+--(data!W9="")+--(data!X9="")+--(data!Y9="")+--(data!Z9="")+--(data!AA9="")+--(data!AB9="")+--(data!AC9="")+--(data!AD9="")+--(data!AE9="")+--(data!AF9="")+--(data!AG9="")+--(data!AH9="")+--(data!AJ9="")+--(data!AL9="")+--(data!AP9="")+--(data!AQ9="")+--(data!AR9="")+--(data!AS9="")+--(data!AT9="")+--(data!AU9="")+--(data!AV9="")+--(data!AW9="")+--(data!AX9="")+--(data!AY9="")+--(data!AZ9="")+--(data!BA9="")+--(data!BB9="")+--(data!BC9="")+--(data!BD9="")+--(data!BE9="")+--(data!BF9="")+--(data!BG9="")+--(data!BH9="")+--(data!BI9="")+--(data!BK9="")+--(data!BM9="")+--(data!J9="")+--(data!K9="")+--(data!L9=""))
A10: =IF(data!A10="","",data!A10) | B10: =IF(data!B10="","",data!B10) | C10: =IF(data!D10="","",data!D10) | D10: =IF(data!A10="","",COUNT(data!O10:AD10)) | E10: =IF(data!A10="","",COUNT(data!AP10:BE10)) | F10: =IF(data!A10="","",IF(COUNT(data!O10:AD10)=16,SUM(data!O10:AD10),"")) | G10: =IF(data!A10="","",IF(COUNT(data!AP10:BE10)=16,SUM(data!AP10:BE10),"")) | H10: =IF(COUNT(data!AH10,data!AI10)=0,"",MAX(data!AH10,data!AI10)) | I10: =IF(COUNT(data!BI10,data!BJ10)=0,"",MAX(data!BI10,data!BJ10)) | J10: =IF(COUNT(data!AJ10,data!AK10)=0,"",MAX(data!AJ10,data!AK10)) | K10: =IF(COUNT(data!BK10,data!BL10)=0,"",MAX(data!BK10,data!BL10)) | L10: =IF(COUNT(data!AL10,data!AM10)=0,"",MIN(data!AL10,data!AM10)) | M10: =IF(COUNT(data!BM10,data!BN10)=0,"",MIN(data!BM10,data!BN10)) | N10: =IF(data!A10="","",IF(OR(F10="",G10=""),0,--(F10=G10))+IF(OR(data!AE10="",data!BF10=""),0,--(data!AE10=data!BF10))+IF(OR(data!AF10="",data!BG10=""),0,--(data!AF10=data!BG10))+IF(OR(data!AG10="",data!BH10=""),0,--(data!AG10=data!BH10))+IF(OR(H10="",I10=""),0,--(H10=I10))+IF(OR(J10="",K10=""),0,--(J10=K10))+IF(OR(L10="",M10=""),0,--(L10=M10))) | O10: =IF(data!D10<>1,"",--(data!O10="")+--(data!P10="")+--(data!Q10="")+--(data!R10="")+--(data!S10="")+--(data!T10="")+--(data!U10="")+--(data!V10="")+--(data!W10="")+--(data!X10="")+--(data!Y10="")+--(data!Z10="")+--(data!AA10="")+--(data!AB10="")+--(data!AC10="")+--(data!AD10="")+--(data!AE10="")+--(data!AF10="")+--(data!AG10="")+--(data!AH10="")+--(data!AJ10="")+--(data!AL10="")+--(data!AP10="")+--(data!AQ10="")+--(data!AR10="")+--(data!AS10="")+--(data!AT10="")+--(data!AU10="")+--(data!AV10="")+--(data!AW10="")+--(data!AX10="")+--(data!AY10="")+--(data!AZ10="")+--(data!BA10="")+--(data!BB10="")+--(data!BC10="")+--(data!BD10="")+--(data!BE10="")+--(data!BF10="")+--(data!BG10="")+--(data!BH10="")+--(data!BI10="")+--(data!BK10="")+--(data!BM10="")+--(data!J10="")+--(data!K10="")+--(data!L10=""))
A11: =IF(data!A11="","",data!A11) | B11: =IF(data!B11="","",data!B11) | C11: =IF(data!D11="","",data!D11) | D11: =IF(data!A11="","",COUNT(data!O11:AD11)) | E11: =IF(data!A11="","",COUNT(data!AP11:BE11)) | F11: =IF(data!A11="","",IF(COUNT(data!O11:AD11)=16,SUM(data!O11:AD11),"")) | G11: =IF(data!A11="","",IF(COUNT(data!AP11:BE11)=16,SUM(data!AP11:BE11),"")) | H11: =IF(COUNT(data!AH11,data!AI11)=0,"",MAX(data!AH11,data!AI11)) | I11: =IF(COUNT(data!BI11,data!BJ11)=0,"",MAX(data!BI11,data!BJ11)) | J11: =IF(COUNT(data!AJ11,data!AK11)=0,"",MAX(data!AJ11,data!AK11)) | K11: =IF(COUNT(data!BK11,data!BL11)=0,"",MAX(data!BK11,data!BL11)) | L11: =IF(COUNT(data!AL11,data!AM11)=0,"",MIN(data!AL11,data!AM11)) | M11: =IF(COUNT(data!BM11,data!BN11)=0,"",MIN(data!BM11,data!BN11)) | N11: =IF(data!A11="","",IF(OR(F11="",G11=""),0,--(F11=G11))+IF(OR(data!AE11="",data!BF11=""),0,--(data!AE11=data!BF11))+IF(OR(data!AF11="",data!BG11=""),0,--(data!AF11=data!BG11))+IF(OR(data!AG11="",data!BH11=""),0,--(data!AG11=data!BH11))+IF(OR(H11="",I11=""),0,--(H11=I11))+IF(OR(J11="",K11=""),0,--(J11=K11))+IF(OR(L11="",M11=""),0,--(L11=M11))) | O11: =IF(data!D11<>1,"",--(data!O11="")+--(data!P11="")+--(data!Q11="")+--(data!R11="")+--(data!S11="")+--(data!T11="")+--(data!U11="")+--(data!V11="")+--(data!W11="")+--(data!X11="")+--(data!Y11="")+--(data!Z11="")+--(data!AA11="")+--(data!AB11="")+--(data!AC11="")+--(data!AD11="")+--(data!AE11="")+--(data!AF11="")+--(data!AG11="")+--(data!AH11="")+--(data!AJ11="")+--(data!AL11="")+--(data!AP11="")+--(data!AQ11="")+--(data!AR11="")+--(data!AS11="")+--(data!AT11="")+--(data!AU11="")+--(data!AV11="")+--(data!AW11="")+--(data!AX11="")+--(data!AY11="")+--(data!AZ11="")+--(data!BA11="")+--(data!BB11="")+--(data!BC11="")+--(data!BD11="")+--(data!BE11="")+--(data!BF11="")+--(data!BG11="")+--(data!BH11="")+--(data!BI11="")+--(data!BK11="")+--(data!BM11="")+--(data!J11="")+--(data!K11="")+--(data!L11=""))
A12: =IF(data!A12="","",data!A12) | B12: =IF(data!B12="","",data!B12) | C12: =IF(data!D12="","",data!D12) | D12: =IF(data!A12="","",COUNT(data!O12:AD12)) | E12: =IF(data!A12="","",COUNT(data!AP12:BE12)) | F12: =IF(data!A12="","",IF(COUNT(data!O12:AD12)=16,SUM(data!O12:AD12),"")) | G12: =IF(data!A12="","",IF(COUNT(data!AP12:BE12)=16,SUM(data!AP12:BE12),"")) | H12: =IF(COUNT(data!AH12,data!AI12)=0,"",MAX(data!AH12,data!AI12)) | I12: =IF(COUNT(data!BI12,data!BJ12)=0,"",MAX(data!BI12,data!BJ12)) | J12: =IF(COUNT(data!AJ12,data!AK12)=0,"",MAX(data!AJ12,data!AK12)) | K12: =IF(COUNT(data!BK12,data!BL12)=0,"",MAX(data!BK12,data!BL12)) | L12: =IF(COUNT(data!AL12,data!AM12)=0,"",MIN(data!AL12,data!AM12)) | M12: =IF(COUNT(data!BM12,data!BN12)=0,"",MIN(data!BM12,data!BN12)) | N12: =IF(data!A12="","",IF(OR(F12="",G12=""),0,--(F12=G12))+IF(OR(data!AE12="",data!BF12=""),0,--(data!AE12=data!BF12))+IF(OR(data!AF12="",data!BG12=""),0,--(data!AF12=data!BG12))+IF(OR(data!AG12="",data!BH12=""),0,--(data!AG12=data!BH12))+IF(OR(H12="",I12=""),0,--(H12=I12))+IF(OR(J12="",K12=""),0,--(J12=K12))+IF(OR(L12="",M12=""),0,--(L12=M12))) | O12: =IF(data!D12<>1,"",--(data!O12="")+--(data!P12="")+--(data!Q12="")+--(data!R12="")+--(data!S12="")+--(data!T12="")+--(data!U12="")+--(data!V12="")+--(data!W12="")+--(data!X12="")+--(data!Y12="")+--(data!Z12="")+--(data!AA12="")+--(data!AB12="")+--(data!AC12="")+--(data!AD12="")+--(data!AE12="")+--(data!AF12="")+--(data!AG12="")+--(data!AH12="")+--(data!AJ12="")+--(data!AL12="")+--(data!AP12="")+--(data!AQ12="")+--(data!AR12="")+--(data!AS12="")+--(data!AT12="")+--(data!AU12="")+--(data!AV12="")+--(data!AW12="")+--(data!AX12="")+--(data!AY12="")+--(data!AZ12="")+--(data!BA12="")+--(data!BB12="")+--(data!BC12="")+--(data!BD12="")+--(data!BE12="")+--(data!BF12="")+--(data!BG12="")+--(data!BH12="")+--(data!BI12="")+--(data!BK12="")+--(data!BM12="")+--(data!J12="")+--(data!K12="")+--(data!L12=""))
A13: =IF(data!A13="","",data!A13) | B13: =IF(data!B13="","",data!B13) | C13: =IF(data!D13="","",data!D13) | D13: =IF(data!A13="","",COUNT(data!O13:AD13)) | E13: =IF(data!A13="","",COUNT(data!AP13:BE13)) | F13: =IF(data!A13="","",IF(COUNT(data!O13:AD13)=16,SUM(data!O13:AD13),"")) | G13: =IF(data!A13="","",IF(COUNT(data!AP13:BE13)=16,SUM(data!AP13:BE13),"")) | H13: =IF(COUNT(data!AH13,data!AI13)=0,"",MAX(data!AH13,data!AI13)) | I13: =IF(COUNT(data!BI13,data!BJ13)=0,"",MAX(data!BI13,data!BJ13)) | J13: =IF(COUNT(data!AJ13,data!AK13)=0,"",MAX(data!AJ13,data!AK13)) | K13: =IF(COUNT(data!BK13,data!BL13)=0,"",MAX(data!BK13,data!BL13)) | L13: =IF(COUNT(data!AL13,data!AM13)=0,"",MIN(data!AL13,data!AM13)) | M13: =IF(COUNT(data!BM13,data!BN13)=0,"",MIN(data!BM13,data!BN13)) | N13: =IF(data!A13="","",IF(OR(F13="",G13=""),0,--(F13=G13))+IF(OR(data!AE13="",data!BF13=""),0,--(data!AE13=data!BF13))+IF(OR(data!AF13="",data!BG13=""),0,--(data!AF13=data!BG13))+IF(OR(data!AG13="",data!BH13=""),0,--(data!AG13=data!BH13))+IF(OR(H13="",I13=""),0,--(H13=I13))+IF(OR(J13="",K13=""),0,--(J13=K13))+IF(OR(L13="",M13=""),0,--(L13=M13))) | O13: =IF(data!D13<>1,"",--(data!O13="")+--(data!P13="")+--(data!Q13="")+--(data!R13="")+--(data!S13="")+--(data!T13="")+--(data!U13="")+--(data!V13="")+--(data!W13="")+--(data!X13="")+--(data!Y13="")+--(data!Z13="")+--(data!AA13="")+--(data!AB13="")+--(data!AC13="")+--(data!AD13="")+--(data!AE13="")+--(data!AF13="")+--(data!AG13="")+--(data!AH13="")+--(data!AJ13="")+--(data!AL13="")+--(data!AP13="")+--(data!AQ13="")+--(data!AR13="")+--(data!AS13="")+--(data!AT13="")+--(data!AU13="")+--(data!AV13="")+--(data!AW13="")+--(data!AX13="")+--(data!AY13="")+--(data!AZ13="")+--(data!BA13="")+--(data!BB13="")+--(data!BC13="")+--(data!BD13="")+--(data!BE13="")+--(data!BF13="")+--(data!BG13="")+--(data!BH13="")+--(data!BI13="")+--(data!BK13="")+--(data!BM13="")+--(data!J13="")+--(data!K13="")+--(data!L13=""))
... A41: =IF(data!A41="","",data!A41) | B41: =IF(data!B41="","",data!B41) | C41: =IF(data!D41="","",data!D41) | D41: =IF(data!A41="","",COUNT(data!O41:AD41)) | E41: =IF(data!A41="","",COUNT(data!AP41:BE41)) | F41: =IF(data!A41="","",IF(COUNT(data!O41:AD41)=16,SUM(data!O41:AD41),"")) | G41: =IF(data!A41="","",IF(COUNT(data!AP41:BE41)=16,SUM(data!AP41:BE41),"")) | H41: =IF(COUNT(data!AH41,data!AI41)=0,"",MAX(data!AH41,data!AI41)) | I41: =IF(COUNT(data!BI41,data!BJ41)=0,"",MAX(data!BI41,data!BJ41)) | J41: =IF(COUNT(data!AJ41,data!AK41)=0,"",MAX(data!AJ41,data!AK41)) | K41: =IF(COUNT(data!BK41,data!BL41)=0,"",MAX(data!BK41,data!BL41)) | L41: =IF(COUNT(data!AL41,data!AM41)=0,"",MIN(data!AL41,data!AM41)) | M41: =IF(COUNT(data!BM41,data!BN41)=0,"",MIN(data!BM41,data!BN41)) | N41: =IF(data!A41="","",IF(OR(F41="",G41=""),0,--(F41=G41))+IF(OR(data!AE41="",data!BF41=""),0,--(data!AE41=data!BF41))+IF(OR(data!AF41="",data!BG41=""),0,--(data!AF41=data!BG41))+IF(OR(data!AG41="",data!BH41=""),0,--(data!AG41=data!BH41))+IF(OR(H41="",I41=""),0,--(H41=I41))+IF(OR(J41="",K41=""),0,--(J41=K41))+IF(OR(L41="",M41=""),0,--(L41=M41))) | O41: =IF(data!D41<>1,"",--(data!O41="")+--(data!P41="")+--(data!Q41="")+--(data!R41="")+--(data!S41="")+--(data!T41="")+--(data!U41="")+--(data!V41="")+--(data!W41="")+--(data!X41="")+--(data!Y41="")+--(data!Z41="")+--(data!AA41="")+--(data!AB41="")+--(data!AC41="")+--(data!AD41="")+--(data!AE41="")+--(data!AF41="")+--(data!AG41="")+--(data!AH41="")+--(data!AJ41="")+--(data!AL41="")+--(data!AP41="")+--(data!AQ41="")+--(data!AR41="")+--(data!AS41="")+--(data!AT41="")+--(data!AU41="")+--(data!AV41="")+--(data!AW41="")+--(data!AX41="")+--(data!AY41="")+--(data!AZ41="")+--(data!BA41="")+--(data!BB41="")+--(data!BC41="")+--(data!BD41="")+--(data!BE41="")+--(data!BF41="")+--(data!BG41="")+--(data!BH41="")+--(data!BI41="")+--(data!BK41="")+--(data!BM41="")+--(data!J41="")+--(data!K41="")+--(data!L41=""))

Sheet 입력안내
A1: 입력 순서
A2: 1. 'data' 시트에만 입력합니다. 1행의 변수명은 SPSS가 그대로 읽으므로 바꾸거나 행을 끼워 넣지 마세요.
A3: 2. 한 사람이 한 행입니다. 최초 참여자 30명 전원(제외자 포함)을 기록지 번호 순서로 입력합니다.
A4: 3. 사전 기록지를 보고 노란·파란 칸(기본, 사전)을 먼저 채우고, 사후 기록지를 보고 초록 칸(사후)을 채웁니다.
A5: 4. 기록지에 없는 값은 비워 둡니다. 0이나 다른 시점 값을 넣지 않습니다(빈칸은 SPSS에서 결측).
A6: 5. 기록지에 적힌 숫자를 그대로 입력합니다. 반올림하거나 단위를 바꾸지 않습니다. 2.44 m가 정수 초로 적혀 있으면 정수로 입력합니다.
A7: 6. 유연성과 2.44 m는 기록지에 2회가 있으면 1회·2회 칸에 각각, 최종값 1개만 있으면 1회 칸에만 입력합니다. 최고값은 분석 때 계산됩니다.
A8: 7. KFES-I는 16문항을 각각 입력합니다. 총점은 분석 때 계산되며, 원래 기록지 총점과 다르면 비고에 적습니다.
A9: 8. 제외자는 incl=0, 제외 사유·상세·시점을 입력합니다. 통제집단 제외자도 실제 사유를 적습니다.
A10: 9. 각 칸에 마우스를 올리면 설명이 나옵니다. 범위 밖 값이나 정해진 코드가 아니면 입력이 막힙니다.
A11: 입력 확인
A12: '입력점검' 시트에서 빨간 칸을 확인합니다: KFES 문항이 1~15개만 입력된 행, 사전=사후 같은 항목이 4개 이상인 행, 포함 대상인데 빈칸이 있는 행.
... A16: SPSS에 직접 입력하고 싶다면 원자료_SPSS_빈파일.sav를 열어 데이터 보기에서 입력하고, 구문의 GET DATA 대신 GET FILE 줄을 사용합니다.
